Workbook

Sheet Day2
A1: 1234 | B1: TEST | C1: E(10-Р АНГИ) II-I | D1: 0 | E1: 0 | F1: 0 | G1: 0 | H1: 0
A2: 166655 | B2: Сарангоо | C2: D(7-Р АНГИ) II-I | D2: 0 | E2: 0 | F2: 0 | G2: 0 | H2: 0 | I2: https://drive.google.com/file/d/11DyCmGNVTG_ivDFBkITgp5iXayINvjDm/view?usp=drivesdk | J2: https://drive.google.com/file/d/1HtN-xkextwP5jX3ZNHzyi7ZxRy1vfE2K/view?usp=drivesdk | K2: https://drive.google.com/file/d/1eZT1Q65jK3nmfGTxsd1ibuYnZhmrfHNq/view?usp=drivesdk | L2: https://drive.google.com/file/d/1ZU_MLXeTHxn-5eq8b2jGGm9zGDRZorXx/view?usp=drivesdk | M2: https://drive.google.com/file/d/107Eb0U6cyS8F8-DFrehECDfwVveJZTqu/view?usp=drivesdk | N2: https://drive.google.com/file/d/1Y4nh1L8uY_fRECrWcmtf1K2HeR5cuFnw/view?usp=drivesdk | O2: https://drive.google.com/file/d/1BPEHm6ZXHCgRfFmFRQUT6pSiB9cVuwuY/view?usp=drivesdk
A3: 83909 | B3: Бүрэнтөгс | C3: D(7-Р АНГИ) II-I | D3: 0 | E3: 0 | F3: 0 | G3: 0 | H3: 0 | I3: https://drive.google.com/file/d/1EWBC07aFDCDgahCeuqVgE54hrquVbSc-/view?usp=drivesdk | J3: https://drive.google.com/file/d/1MzglUGxXQT7PWJ1PmlnKAvUI3DZe089Y/view?usp=drivesdk | K3: https://drive.google.com/file/d/1oWgpZWjX25_BrcwzPD8TlAv56TVQXetw/view?usp=drivesdk | L3: https://drive.google.com/file/d/1YTGacUl6IeRadlsOuAiJbRqouTTvE777/view?usp=drivesdk | M3: https://drive.google.com/file/d/1znuL8Ylf7f3Tl07WEivm4XxmLSfVukT7/view?usp=drivesdk
A4: 88991 | B4: Энхтүвшин | C4: D(7-Р АНГИ) II-I | D4: 0 | E4: 0 | F4: 0 | G4: 0 | H4: 0 | I4: https://drive.google.com/file/d/1IPFA-ms8bEi33KUPGkQ0cFlHHp8IrZB4/view?usp=drivesdk | J4: https://drive.google.com/file/d/12MMwL-ynA92Sl5eW_WQNCkhCy7nOyb41/view?usp=drivesdk
A5: 83927 | B5: Сүх-Очир | C5: D(7-Р АНГИ) II-I | D5: 0 | E5: 0 | F5: 0 | G5: 0 | H5: 0 | I5: https://drive.google.com/file/d/1GVkL87DN76YIEr0KPF0U_iQmM14TmFwX/view?usp=drivesdk | J5: https://drive.google.com/file/d/1vkURYVCjNWV4I9-ao8QQM6X_RXH3vFqs/view?usp=drivesdk
A6: 74051 | B6: Бадмаараг | C6: D(7-Р АНГИ) II-I | D6: 0 | E6: 0 | F6: 0 | G6: 0 | H6: 0 | I6: https://drive.google.com/file/d/12qfaI6trCToyD5w8vXP63rO7Xh5PYwwe/view?usp=drivesdk
A7: 112064 | B7: Батмөнх | C7: D(7-Р АНГИ) II-I | D7: 0 | E7: 0 | F7: 0 | G7: 0 | H7: 0 | I7: https://drive.google.com/file/d/18TuqNSldFtjJdgIYZoCrtbK0dMfbISSY/view?usp=drivesdk
A8: 115704 | B8: Амин-Эрдэнэ | C8: D(7-Р АНГИ) II-I | D8: 0 | E8: 0 | F8: 0 | G8: 0 | H8: 0 | I8: https://drive.google.com/file/d/15vJx6KqD4KFCL-i0Ki6OFEuxj__ymFrz/view?usp=drivesdk
A9: 223462 | B9: Цэлмэг | C9: D(7-Р АНГИ) II-I | D9: 0 | E9: 0 | F9: 0 | G9: 0 | H9: 0 | I9: https://drive.google.com/file/d/1ku-vTjU9obw3YDh05cYCh8ITvz_SRzgj/view?usp=drivesdk | J9: https://drive.google.com/file/d/1blYmeVBhkTlwm2Hy51MT8MMiTNHn4AAQ/view?usp=drivesdk
A10: 115699 | B10: Буяндалай | C10: D(7-Р АНГИ) II-I | D10: 0 | E10: 0 | F10: 0 | G10: 0 | H10: 0 | I10: https://drive.google.com/file/d/1NPafRRwQMa3vy74bKJgh9W4ysZ-6zf9u/view?usp=drivesdk | J10: https://drive.google.com/file/d/1rsAa8FdDdVTxsMYhZYWdky2fwHHpQ3cG/view?usp=drivesdk
A11: 141476 | B11: Ганбаатар | C11: D(7-Р АНГИ) II-I | D11: 0 | E11: 0 | F11: 0 | G11: 0 | H11: 0 | I11: https://drive.google.com/file/d/1IOEmhmAQboPoz1QuC3d2HuRG8qIpDYS2/view?usp=drivesdk | J11: https://drive.google.com/file/d/1o2IKPy73RKFglyzNf5U-hNOckpsZAIQx/view?usp=drivesdk
A12: 133280 | B12: Хосбилэг | C12: D(7-Р АНГИ) II-I | D12: 0 | E12: 0 | F12: 0 | G12: 0 | H12: 0 | I12: https://drive.google.com/file/d/1Oml4Q7sOyqZRh-2a7pW2nfUwv312SXaT/view?usp=drivesdk
A13: 74043 | B13: Бямбадорж | C13: D(7-Р АНГИ) II-I | D13: 0 | E13: 0 | F13: 0 | G13: 0 | H13: 0 | I13: https://drive.google.com/file/d/1HtRThoTc_QWkE7Fmx-Gzffzoq4Y-zxE9/view?usp=drivesdk
A14: 165643 | B14: Манлай | C14: D(7-Р АНГИ) II-I | D14: 0 | E14: 0 | F14: 0 | G14: 0 | H14: 0 | I14: https://drive.google.com/file/d/1cDF0pLBKDffctIX50Exf3tAXe1V6RKjC/view?usp=drivesdk
A15: 109722 | B15: Энхжаргал | C15: D(7-Р АНГИ) II-I | D15: 0 | E15: 0 | F15: 0 | G15: 0 | H15: 0 | I15: https://drive.google.com/file/d/1TXx3yi1X3M7MyfsNVTS4fxDfj-qWxuxl/view?usp=drivesdk
A16: 111753 | B16: Амина | C16: D(7-Р АНГИ) II-I | D16: 0 | E16: 0 | F16: 0 | G16: 0 | H16: 0 | I16: https://drive.google.com/file/d/1dnqUkA8vLB29qo7iNkaMq_XGPY8ISr2i/view?usp=drivesdk
A17: 220595 | B17: Оюун-Ундрал | C17: D(7-Р АНГИ) II-I | D17: 0 | E17: 0 | F17: 0 | G17: 0 | H17: 0 | I17: https://drive.google.com/file/d/1n9fUjJBhhPhk9J0T9e8J1mLwwScn0Lao/view?usp=drivesdk | J17: https://drive.google.com/file/d/1PFLtk2_7h275wEnzgLcNElT4h_MUNC7N/view?usp=drivesdk
A18: 181522 | B18: Анужин | C18: D(7-Р АНГИ) II-I | D18: 0 | E18: 0 | F18: 0 | G18: 0 | H18: 0 | I18: https://drive.google.com/file/d/1i85GIcMvPscivRLONpOQQQyDClC9N7ar/view?usp=drivesdk | J18: https://drive.google.com/file/d/1uSswBPaqjWZJrccSXjK2yFxMFd8cMK6s/view?usp=drivesdk
A19: 165616 | B19: Ижилзаяа | C19: D(7-Р АНГИ) II-I | D19: 0 | E19: 0 | F19: 0 | G19: 0 | H19: 0 | I19: https://drive.google.com/file/d/1elDhD-OY-t6BPbY0x11nsmTSUfwYdHQg/view?usp=drivesdk | J19: https://drive.google.com/file/d/1S5EpKPtg4Hqcr9mnPkH2xe8JZUOZyZAY/view?usp=drivesdk | K19: https://drive.google.com/file/d/1zA2spbK8YEwBB-tjf4AKfLpgHUhITEZ-/view?usp=drivesdk
A20: 222710 | B20: Далай | C20: D(7-Р АНГИ) II-I | D20: 0 | E20: 0 | F20: 0 | G20: 0 | H20: 0 | I20: https://drive.google.com/file/d/1XS_SQalBk-Y7KuQxz1z2i-mmADKdqCQe/view?usp=drivesdk | J20: https://drive.google.com/file/d/12Owkhne6KSMexCmQKDOBjwNfkiCy4Jjw/view?usp=drivesdk | K20: https://drive.google.com/file/d/1b90E__hlfp5mUOBcK9H2_UcwQZ74WNJB/view?usp=drivesdk | L20: https://drive.google.com/file/d/1lJYQcwyloEVXF3XAP9Og5UqzYRYGoTUc/view?usp=drivesdk
A21: 187530 | B21: Итгэл | C21: D(7-Р АНГИ) II-I | D21: 0 | E21: 0 | F21: 0 | G21: 0 | H21: 0 | I21: https://drive.google.com/file/d/1ugMOpblkWYJkokPFQyvtUHVIWywsxB4f/view?usp=drivesdk | J21: https://drive.google.com/file/d/1Bp9lBvMoUICePULZ7rxotKNnzKGOl1i0/view?usp=drivesdk | K21: https://drive.google.com/file/d/1g8DR91c5UC4As_NSl4CvrDCshzxH2ijC/view?usp=drivesdk | L21: https://drive.google.com/file/d/1jkg5PSPWcyyN06tiuKFaf2yqZAIQp9-v/view?usp=drivesdk
A22: 138766 | B22: Оюунхорол | C22: D(7-Р АНГИ) II-I | D22: 0 | E22: 0 | F22: 0 | G22: 0 | H22: 0
A23: 174382 | B23: Биндэръяа | C23: D(7-Р АНГИ) II-I | D23: 0 | E23: 0 | F23: 0 | G23: 0 | H23: 0 | I23: https://drive.google.com/file/d/1VCZBPprNaCMdUpYEwnG8xByTRFQbLVJ3/view?usp=drivesdk | J23: https://drive.google.com/file/d/1Zpz-sQly7pSuEgCgHtfUn8_TdUdqd8dU/view?usp=drivesdk | K23: https://drive.google.com/file/d/146BjmAS3wqExeBAgvZEPxzOZ4vbi7-m1/view?usp=drivesdk | L23: https://drive.google.com/file/d/1OCYiVQPA-KRI19PjyXagY2mlx0gKxq_i/view?usp=drivesdk
A24: 117485 | B24: Тайванжаргал | C24: D(7-Р АНГИ) II-I | D24: 0 | E24: 0 | F24: 0 | G24: 0 | H24: 0 | I24: https://drive.google.com/file/d/19Tki1n01ji0F6Kk2c4JrYlQwojtmfvW4/view?usp=drivesdk | J24: https://drive.google.com/file/d/1h99HWDSBxO6GeXeXW4UznspzEiVXF-4l/view?usp=drivesdk | K24: https://drive.google.com/file/d/1Zka1HBvZjh7KWe3VCARggz-TnAlFRUJm/view?usp=drivesdk | L24: https://drive.google.com/file/d/1d2F-2vL5lY5Vb38HlP9Vwqbq7NXKSGwd/view?usp=drivesdk
A25: 186793 | B25: Алтанхүү | C25: D(7-Р АНГИ) II-I | D25: 0 | E25: 0 | F25: 0 | G25: 0 | H25: 0 | I25: https://drive.google.com/file/d/1rYcSocIQ3zaNOiebP_iZQ3hEgIPnqqu3/view?usp=drivesdk | J25: https://drive.google.com/file/d/1jLoSjYiNrDKYs45mw7Q8MUNPiImYvudJ/view?usp=drivesdk | K25: https://drive.google.com/file/d/16pCLv7_bSQhA-g71MCzi7h57KcqXM_Iy/view?usp=drivesdk | L25: https://drive.google.com/file/d/1J4kxPjXYWPOEM26jawngwzrJddMC9P3K/view?usp=drivesdk
A26: 174878 | B26: Тэлмүүн | C26: D(7-Р АНГИ) II-I | D26: 0 | E26: 0 | F26: 0 | G26: 0 | H26: 0 | I26: https://drive.google.com/file/d/1jeaFCCUxj5D0DBbmP5p9K0NylgEeBXb1/view?usp=drivesdk | J26: https://drive.google.com/file/d/1NECfY3EXgdUmmqmVuDiJEd11saT-owKb/view?usp=drivesdk | K26: https://drive.google.com/file/d/10AmW4F_lWiCtCWfI-fdkBvboITpyKurg/view?usp=drivesdk | L26: https://drive.google.com/file/d/1Ryun7BTGNZhmt6TXZUEo2ipdYDdS7zcB/view?usp=drivesdk
A27: 117510 | B27: Аминцэцэг | C27: D(7-Р АНГИ) II-I | D27: 0 | E27: 0 | F27: 0 | G27: 0 | H27: 0 | I27: https://drive.google.com/file/d/1usFDPjQ0bx7KwtGjfYFQX4FLK_UeFdcG/view?usp=drivesdk | J27: https://drive.google.com/file/d/1dygbDv7m2JxOi7dmATTAKF5UDfz6-hEV/view?usp=drivesdk | K27: https://drive.google.com/file/d/1wrFhVsZVWjDZuMTgPKD_FeLvJB-26npy/view?usp=drivesdk | L27: https://drive.google.com/file/d/1KYf5DKIs_zflhqSGEP0uiRvny7yITpXZ/view?usp=drivesdk
A28: 111570 | B28: Аружан | C28: D(7-Р АНГИ) II-I | D28: 0 | E28: 0 | F28: 0 | G28: 0 | H28: 0 | I28: https://drive.google.com/file/d/1AGsbmUxGBHIpaiJIzAOIjP2AgtRPpo10/view?usp=drivesdk | J28: https://drive.google.com/file/d/1fAtbDu1KiwFYDzwzWuovrCrEc6OIwt2j/view?usp=drivesdk
A29: 125987 | B29: Ану-Үжин | C29: D(7-Р АНГИ) II-I | D29: 0 | E29: 0 | F29: 0 | G29: 0 | H29: 0 | I29: https://drive.google.com/file/d/1xmi8HhEne-XSPV5_75Caz64anAPFntsy/view?usp=drivesdk | J29: https://drive.google.com/file/d/1xDDhi1B8xB-1mjCfTIVqpIe23wqclHDR/view?usp=drivesdk | K29: https://drive.google.com/file/d/19_ghNUg5_rBAGX8a3AAjwR-DOwFkImKl/view?usp=drivesdk
A30: 223952 | B30: Нансалмаа | C30: D(7-Р АНГИ) II-I | D30: 0 | E30: 0 | F30: 0 | G30: 0 | H30: 0 | I30: https://drive.google.com/file/d/17MCY7DnwacUgqS9nnO_5FrzIWrlA0Bes/view?usp=drivesdk | J30: https://drive.google.com/file/d/1oZ_IEv-WTRqxq0-7nnoaZnnoCE6s1fJc/view?usp=drivesdk | K30: https://drive.google.com/file/d/1OCgakN8BZBLd7h0QdRD2rq-WCabwPTSd/view?usp=drivesdk | L30: https://drive.google.com/file/d/1vnss1A3B0MzRWtypVz4W77iTaoKIJsuH/view?usp=drivesdk
A31: 109847 | B31: Анужин | C31: D(7-Р АНГИ) II-I | D31: 0 | E31: 0 | F31: 0 | G31: 0 | H31: 0 | I31: https://drive.google.com/file/d/1CEue2-2gqriODsNjhQFskdeCKugWxIic/view?usp=drivesdk | J31: https://drive.google.com/file/d/1DiQ9NiD-2SFeXpSV0jDxY5X9pW9VmTs7/view?usp=drivesdk | K31: https://drive.google.com/file/d/1KWOXmSPvkE_L61EGyOG8mXeVAV0veVFB/view?usp=drivesdk
A32: 88997 | B32: Мянганбаяр | C32: D(7-Р АНГИ) II-I | D32: 0 | E32: 0 | F32: 0 | G32: 0 | H32: 0 | I32: https://drive.google.com/file/d/1IgbeVKCkSLFIwjud2HgrnCIUQUPIoJM7/view?usp=drivesdk
A33: 188003 | B33: Энхжаргал | C33: D(7-Р АНГИ) II-I | D33: 0 | E33: 0 | F33: 0 | G33: 0 | H33: 0 | I33: https://drive.google.com/file/d/1WRzunmP2eC_QdEPXjjRbnr_vMX196fT1/view?usp=drivesdk | J33: https://drive.google.com/file/d/1ZmvPMz6sP6rowJXp1a1g-Kv_6177_hm7/view?usp=drivesdk | K33: https://drive.google.com/file/d/1-Osw0Tn-YmPZXy4Yfu6YLSt8ecsr0zPk/view?usp=drivesdk | L33: https://drive.google.com/file/d/1TBXwGSr57m20I07r3qe32mm4sVy3Y4f7/view?usp=drivesdk
A34: 174562 | B34: Бат-Ирээдүй | C34: D(7-Р АНГИ) II-I | D34: 0 | E34: 0 | F34: 0 | G34: 0 | H34: 0 | I34: https://drive.google.com/file/d/1rmNLwsx59Qx4W2-mByQyC3f4QTAyuSjw/view?usp=drivesdk | J34: https://drive.google.com/file/d/1D5u0R93iNNZJdLDOXXZoACiosKiH_x50/view?usp=drivesdk | K34: https://drive.google.com/file/d/10Yld1EfqOEp3zeYR7waqJUusz5P76NjD/view?usp=drivesdk | L34: https://drive.google.com/file/d/1Vnz8m1ONpyyVVI8OsBapI-hjY2LEhoyn/view?usp=drivesdk
A35: 111331 | B35: Хишигмаа | C35: D(7-Р АНГИ) II-I | D35: 0 | E35: 0 | F35: 0 | G35: 0 | H35: 0 | I35: https://drive.google.com/file/d/1--d4xMXodBCFH_9fLl2K4rIG_uxVFCjr/view?usp=drivesdk | J35: https://drive.google.com/file/d/1Z94BP3UGA8qYLP-4jISUsqVmyic8lcsY/view?usp=drivesdk
A36: 74053 | B36: Эрхэмбэлгэ | C36: D(7-Р АНГИ) II-I | D36: 0 | E36: 0 | F36: 0 | G36: 0 | H36: 0 | I36: https://drive.google.com/file/d/1c01n9iGXwRQlmJCq1vL7tEhMy_RZ2CD7/view?usp=drivesdk | J36: https://drive.google.com/file/d/1DZpJ29fJdG-cLNZKT1YQjbEy2Tep1J6Z/view?usp=drivesdk
A37: 83920 | B37: Хулан | C37: D(7-Р АНГИ) II-I | D37: 0 | E37: 0 | F37: 0 | G37: 0 | H37: 0 | I37: https://drive.google.com/file/d/1abV_IEfeUOoUFjw8legxMWgyY_Oz7ZbN/view?usp=drivesdk | J37: https://drive.google.com/file/d/1KLAlYwJ4YVKSzA-0m4P7CkaVBixc3es4/view?usp=drivesdk | K37: https://drive.google.com/file/d/1NMbYP9jTl5oHJpR9rByoLWIj7IGuOwJZ/view?usp=drivesdk
A38: 175004 | B38: Чингүүн | C38: D(7-Р АНГИ) II-I | D38: 0 | E38: 0 | F38: 0 | G38: 0 | H38: 0 | I38: https://drive.google.com/file/d/1mJXbYdt71KGqCmdXiJY4xzxD-KL0FiOt/view?usp=drivesdk | J38: https://drive.google.com/file/d/1QSXcqD4tjrkP1Myh0NPMZXRx6c3-2ya4/view?usp=drivesdk
A39: 95427 | B39: Өнөмөнхлэй | C39: D(7-Р АНГИ) II-I | D39: 0 | E39: 0 | F39: 0 | G39: 0 | H39: 0 | I39: https://drive.google.com/file/d/1ISP0-XXiWrc0x7q8IO1rm7Y7bZ8JskY1/view?usp=drivesdk | J39: https://drive.google.com/file/d/1KihAV4QbUYvjtEsIskinRr9Rr6gA29he/view?usp=drivesdk | K39: https://drive.google.com/file/d/12f_fDKG5R8VXoS-zgdQ8rAM2QsDAeH_J/view?usp=drivesdk | L39: https://drive.google.com/file/d/10wMg9NgDzALkcHieCPg6D2_26nuEw9px/view?usp=drivesdk
A40: 124028 | B40: Цэлмэг | C40: D(7-Р АНГИ) II-I | D40: 0 | E40: 0 | F40: 0 | G40: 0 | H40: 0 | I40: https://drive.google.com/file/d/1H46UyJ-qhljzlujWzwA-I97cpafozqLp/view?usp=drivesdk | J40: https://drive.google.com/file/d/1dVL6Eunm-sQgfY9nCOOhqvIZ6pNacN-i/view?usp=drivesdk
...

Sheet Day1
A1: 1234 | B1: TEST | C1: E(10-Р АНГИ) II-I | D1: 1 | E1: 0 | F1: 0 | G1: 0 | H1: 5
A2: 186864 | B2: Хишигжаргал | C2: E(10-Р АНГИ) II-I | D2: 0 | E2: 2 | F2: 0 | G2: 0 | H2: 0 | I2: https://drive.google.com/file/d/1iLTmKIm0TEPhpjFzVJKYMx0w89XdaFs_/view?usp=drivesdk | J2: https://drive.google.com/file/d/17HQCUFl6640pyjyICZnvVRwX0pD7WmVu/view?usp=drivesdk | K2: https://drive.google.com/file/d/1hmqUBNDOVV9wHRgZDXbGKalz-08D9QnO/view?usp=drivesdk
A3: 108195 | B3: Тэлмүүн | C3: E(10-Р АНГИ) II-I | D3: 1 | E3: 0 | F3: 0 | G3: 0 | H3: 0 | I3: https://drive.google.com/file/d/1GD-ExkBSVHOn3kDXROZ90Y8KInq06Wyf/view?usp=drivesdk
A4: 81407 | B4: Төгсжаргал | C4: E(10-Р АНГИ) II-I | D4: 7 | E4: 7 | F4: 0 | G4: 0 | H4: 0 | I4: https://drive.google.com/file/d/1YBXhJcHL37RYZuuYAtVnLqyu7x9ozdeb/view?usp=drivesdk | J4: https://drive.google.com/file/d/1NpGga28vXRgej5mcPcuM-HslI0oY3hZg/view?usp=drivesdk | K4: https://drive.google.com/file/d/1X4l8wypMi8SMS3eqVcZw6_ZwF4iWcIsZ/view?usp=drivesdk | L4: https://drive.google.com/file/d/16_uNq-DG4uJmXuwrWk4UdS3qkAroAcmf/view?usp=drivesdk | M4: https://drive.google.com/file/d/1gwBupHnra2xpsQZGwu_3TT1Mjw0tApt6/view?usp=drivesdk | N4: https://drive.google.com/file/d/16YeAp1hToyDXNh6pEhxsPMoo2sjzS8UV/view?usp=drivesdk | O4: https://drive.google.com/file/d/14hgziGdYOlSH27WYQJ3q9JyHfrtw2zoE/view?usp=drivesdk | P4: https://drive.google.com/file/d/1X19dr38FC_ODc_324j_30zWKLKbY-NGb/view?usp=drivesdk
A5: 51485 | B5: Тэнүүннаран | C5: E(10-Р АНГИ) II-I | D5: 4 | E5: 0 | F5: 0 | G5: 0 | H5: 0 | I5: https://drive.google.com/file/d/1zDwFNmoVqeYVuZ7vhR0xUd-zIUG9ai_f/view?usp=drivesdk | J5: https://drive.google.com/file/d/1yoMPc0PZDIFGc_pqrZIm3X6iw-8fprh_/view?usp=drivesdk | K5: https://drive.google.com/file/d/1O8p7MSRI_dMyHzj4MuOI7Kul6wm_Vtri/view?usp=drivesdk | L5: https://drive.google.com/file/d/16b95llLASzz-3hbjxGP6UQp9_v5v03On/view?usp=drivesdk
A6: 187836 | B6: Нуршаш | C6: E(10-Р АНГИ) II-I | D6: 1 | E6: 3 | F6: 0 | G6: 0 | H6: 0 | I6: https://drive.google.com/file/d/1r1pmPu9A933OyUIGzju3P-iLmfM-DtIR/view?usp=drivesdk | J6: https://drive.google.com/file/d/1thSgiU28g9r9iMzX1MUMzUsPQ_J2pStK/view?usp=drivesdk | K6: https://drive.google.com/file/d/1QIBUHpMWGtqaB4VaKvStMLwVOqeGwjl8/view?usp=drivesdk | L6: https://drive.google.com/file/d/1R-E9QhXMBNv3H6ly4G6DWxgVUycT_7j0/view?usp=drivesdk | M6: https://drive.google.com/file/d/1JpKyEKhl4LeTOKKxS05UCz625b3bv_73/view?usp=drivesdk
A7: 72371 | B7: Азбаяр | C7: E(10-Р АНГИ) II-I | D7: 7 | E7: 4 | F7: 0 | G7: 0 | H7: 0 | I7: https://drive.google.com/file/d/11uPMjaPH9vQ5WpJOaQT5mU8Ve7m3QqX3/view?usp=drivesdk | J7: https://drive.google.com/file/d/1PMgt1BBuiFPwTcqv8yjbQvzO6jcZVRWS/view?usp=drivesdk | K7: https://drive.google.com/file/d/1-vuj5XKWKJ-2AjLCAnhqJI2q27G9Dodh/view?usp=drivesdk | L7: https://drive.google.com/file/d/1F8kb6rL7mzjFtegUYOnSi499xpz4m0Wa/view?usp=drivesdk | M7: https://drive.google.com/file/d/1tnQrciC-DO0o5iXGo6EEbJN6RG1h6EGe/view?usp=drivesdk
A8: 50160 | B8: Цэлмүүн | C8: E(10-Р АНГИ) II-I | D8: 7 | E8: 0 | F8: 0 | G8: 0 | H8: 0 | I8: https://drive.google.com/file/d/1dzWpuLazN92IMN3GxuGJSy8GMW-hVgtY/view?usp=drivesdk | J8: https://drive.google.com/file/d/1PRb7KJ9CVPGY5Q6sZyn6TLUe2MUH9KJt/view?usp=drivesdk | K8: https://drive.google.com/file/d/1mALvpQPfgYPCIcHoDlIiZpMQgyJ8kocX/view?usp=drivesdk | L8: https://drive.google.com/file/d/1cHA-_z1qkJvbNXkTaCW5nfCJHGLI7wiy/view?usp=drivesdk
A9: 110925 | B9: Саруул | C9: E(10-Р АНГИ) II-I | D9: 7 | E9: 4 | F9: 0 | G9: 0 | H9: 0 | I9: https://drive.google.com/file/d/1mfUyZGKa4cyV-LKbwZb-It6TKnKdbh6c/view?usp=drivesdk | J9: https://drive.google.com/file/d/14vlFZjFTQM0lKCLliXvkRupTENwO40vJ/view?usp=drivesdk | K9: https://drive.google.com/file/d/1S7DmyQh6efE9YneoZ8ohDfX6HufAlO2a/view?usp=drivesdk | L9: https://drive.google.com/file/d/1MYyW_OMpFwnFbI2L8PJkI0OF02-IR3BL/view?usp=drivesdk
A10: 81414 | B10: Батсүлд | C10: E(10-Р АНГИ) II-I | D10: 7 | E10: 2 | F10: 0 | G10: 0 | H10: 0 | I10: https://drive.google.com/file/d/1v7a7Tu_fMDK4suiJ3eg8l6usSmqqPhyY/view?usp=drivesdk
A11: 187841 | B11: Маралаа | C11: E(10-Р АНГИ) II-I | D11: 1 | E11: 4 | F11: 0 | G11: 0 | H11: 0 | I11: https://drive.google.com/file/d/1rM2aI0ycx2nTmNiPB2iQ9kc6BeX__Tm4/view?usp=drivesdk | J11: https://drive.google.com/file/d/1gM77oAHcfA1lCxNvZ_vTLRr0Q_-WB0b8/view?usp=drivesdk | K11: https://drive.google.com/file/d/1acfiQudsbplUorea62TT9SqNbm2AuCYt/view?usp=drivesdk
A12: 206976 | B12: Энхмэнд | C12: E(10-Р АНГИ) II-I | D12: 7 | E12: 2 | F12: 0 | G12: 0 | H12: 0 | I12: https://drive.google.com/file/d/1YOtsmgqUR1DzV1YbMPnWrxTg80IlNPQ5/view?usp=drivesdk
A13: 212268 | B13: Цэнгүүжин | C13: E(10-Р АНГИ) II-I | D13: 7 | E13: 0 | F13: 0 | G13: 0 | H13: 0 | I13: https://drive.google.com/file/d/1-ObO1QsttJf-ReyOXKMo6o2fC1xRGKyO/view?usp=drivesdk | J13: https://drive.google.com/file/d/1ACGJyr54eOYBpEDyOZpAEoLUHfWsI5cG/view?usp=drivesdk | K13: https://drive.google.com/file/d/1YhEDdTaKA9TK342HaQC3xVFpPklrnfJ1/view?usp=drivesdk | L13: https://drive.google.com/file/d/1g_9O0ULJYqI8RzxebnCGqHrPKsXE3Mn9/view?usp=drivesdk
A14: 181339 | B14: Цэлмүүннаран | C14: E(10-Р АНГИ) II-I | D14: 0 | E14: 0 | F14: 0 | G14: 0 | H14: 0 | I14: https://drive.google.com/file/d/1AWVXOwdx6nJg1Nfh1KVQN1bUX9B49utR/view?usp=drivesdk | J14: https://drive.google.com/file/d/1BBZR49jFns7QeaQvwZN2j2YeiQAmivX5/view?usp=drivesdk | K14: https://drive.google.com/file/d/1XOgTtaCzGLCDaro1yqLymfv76uAMW-PG/view?usp=drivesdk | L14: https://drive.google.com/file/d/1d7b0yuBeJq3SIyKbOX-b-EYMqKdma1oh/view?usp=drivesdk
A15: 52574 | B15: Цэцэн | C15: E(10-Р АНГИ) II-I | D15: 7 | E15: 2 | F15: 0 | G15: 0 | H15: 0 | I15: https://drive.google.com/file/d/16sdHVtmZFu4QS4GjRFOdKqBVj9sv6OX3/view?usp=drivesdk
A16: 81422 | B16: Мөнгөншагай | C16: E(10-Р АНГИ) II-I | D16: 7 | E16: 4 | F16: 0 | G16: 0 | H16: 0 | I16: https://drive.google.com/file/d/1AWUuH2nrIhH8xP-VRYwQInHuEeau85T_/view?usp=drivesdk | J16: https://drive.google.com/file/d/15hf_cj-tfJ401chUlXnBEy0s3EcyXmOx/view?usp=drivesdk | K16: https://drive.google.com/file/d/1RbwubB2jLi0jrt0URcMcPdVgvmDpGgN4/view?usp=drivesdk
A17: 136996 | B17: Нандин-Эрдэнэ | C17: E(10-Р АНГИ) II-I | D17: 7 | E17: 0 | F17: 0 | G17: 0 | H17: 0 | I17: https://drive.google.com/file/d/1u7B4UDvOPvlPdE0nbRzjyIL_V54Gxecd/view?usp=drivesdk | J17: https://drive.google.com/file/d/1hIw2n5g3NaG2KTyeBCVdFjJDq98KXz81/view?usp=drivesdk | K17: https://drive.google.com/file/d/14n7_INwQBwcqrvq0GJTz_DUimIGn8Adh/view?usp=drivesdk
A18: 119572 | B18: Зулаа | C18: E(10-Р АНГИ) II-I | D18: 7 | E18: 2 | F18: 0 | G18: 0 | H18: 0 | I18: https://drive.google.com/file/d/10Is3pvQsPQD0EDccLT5e0RQxSd7EAfmL/view?usp=drivesdk | J18: https://drive.google.com/file/d/1zqsF_WdBrMcxx-QsImnbP7oybgXyn67I/view?usp=drivesdk | K18: https://drive.google.com/file/d/1nQb1LOXVBrwHf0PrjSp1WhydKq_SA5i9/view?usp=drivesdk
A19: 111815 | B19: Түвшинтөгс | C19: E(10-Р АНГИ) II-I | D19: 7 | E19: 2 | F19: 0 | G19: 0 | H19: 0 | I19: https://drive.google.com/file/d/1Q0WfxtbOrAjELH5NbiiZBIiJbROTV0nS/view?usp=drivesdk
A20: 127024 | B20: Дашцэрэн | C20: E(10-Р АНГИ) II-I | D20: 7 | E20: 0 | F20: 0 | G20: 0 | H20: 0 | I20: https://drive.google.com/file/d/1vcG7WGv-GXVczciW9gPOxusgRwSij7CD/view?usp=drivesdk
A21: 81436 | B21: Тэмүүжин | C21: E(10-Р АНГИ) II-I | D21: 7 | E21: 3 | F21: 0 | G21: 0 | H21: 0 | I21: https://drive.google.com/file/d/1AZidsCeiZPYD4PDH8gbw2mytLGXfZR8p/view?usp=drivesdk
A22: 155666 | B22: Келбахыт | C22: E(10-Р АНГИ) II-I | D22: 0 | E22: 0 | F22: 0 | G22: 0 | H22: 0 | I22: https://drive.google.com/file/d/1szWvH7zOvAeBrdNrcH3SROsFbXNatu9B/view?usp=drivesdk | J22: https://drive.google.com/file/d/1qwh4ymwm0sS_2nZXoTk7SXVyJU8BFucX/view?usp=drivesdk
A23: 118935 | B23: Цэрэндонров | C23: E(10-Р АНГИ) II-I | D23: 0 | E23: 2 | F23: 0 | G23: 0 | H23: 0 | I23: https://drive.google.com/file/d/1de-kcd0PKtoDNwkRk64MJFUWshjmfGPI/view?usp=drivesdk | J23: https://drive.google.com/file/d/1bXZ3phf28dOusGd1QeZtJlYtFH-ElNhd/view?usp=drivesdk | K23: https://drive.google.com/file/d/11dZCxPwT_F3_r-Fl2Xz9f_37ejgjpIAq/view?usp=drivesdk | L23: https://drive.google.com/file/d/14XS7vjxQQIvRU2EoTJ29GrKwwZGoTpTf/view?usp=drivesdk
A24: 186921 | B24: Номин | C24: E(10-Р АНГИ) II-I | D24: 0 | E24: 2 | F24: 0 | G24: 0 | H24: 0 | I24: https://drive.google.com/file/d/1mCahJ5rKmQrqTzkt-KFcmCKZwUxWu9hZ/view?usp=drivesdk | J24: https://drive.google.com/file/d/1rTsyHp9V8yPXe-Pt4sg-5zEMzaruShuK/view?usp=drivesdk
A25: 118299 | B25: Адьшаа | C25: E(10-Р АНГИ) II-I | D25: 7 | E25: 4 | F25: 0 | G25: 0 | H25: 0 | I25: https://drive.google.com/file/d/1VI9xz-_GjKsTeWiO7FrhdJkKbqP7tGrz/view?usp=drivesdk | J25: https://drive.google.com/file/d/1IlhRHfhzS9JedEKAZhUVY6AHdqFic6N4/view?usp=drivesdk | K25: https://drive.google.com/file/d/1iynwVSYo9hYwfOHK8JsTw5tlc5E2yTUN/view?usp=drivesdk
A26: 118641 | B26: Маргад | C26: E(10-Р АНГИ) II-I | D26: 7 | E26: 4 | F26: 0 | G26: 0 | H26: 0 | I26: https://drive.google.com/file/d/1V2vRYuiDvcOrUlmUz1x9FWCTDYPBjUT1/view?usp=drivesdk | J26: https://drive.google.com/file/d/102MYKNIZtcUq8m3RLgCEHZWBHOXdTBqp/view?usp=drivesdk | K26: https://drive.google.com/file/d/1fLjv7fKNGz3i59qm2z1RyCVFgFbufz05/view?usp=drivesdk
A27: 96536 | B27: Ариунжаргал | C27: E(10-Р АНГИ) II-I | D27: 0 | E27: 2 | F27: 0 | G27: 0 | H27: 0 | I27: https://drive.google.com/file/d/1mWuE5v0f5rrI3ZtfEQ6q41iu1HKT-i3n/view?usp=drivesdk | J27: https://drive.google.com/file/d/18kBvzw3TXTny3iMqWm6PryUsraL42cyZ/view?usp=drivesdk
A28: 115673 | B28: Энхтогтох | C28: E(10-Р АНГИ) II-I | D28: 4 | E28: 0 | F28: 0 | G28: 0 | H28: 0 | I28: https://drive.google.com/file/d/1GNAWYq2nYQe4jPK3_XoYILcfz-N-CWT1/view?usp=drivesdk | J28: https://drive.google.com/file/d/16VOCSAx5ChhapOUHxMMI7_hbxm0CdfXm/view?usp=drivesdk | K28: https://drive.google.com/file/d/1VxNaxtT3ODxJESwpwZbiFNDzYayhq_2G/view?usp=drivesdk
A29: 175146 | B29: Мөрөн | C29: E(10-Р АНГИ) II-I | D29: 0 | E29: 0 | F29: 0 | G29: 0 | H29: 0 | I29: https://drive.google.com/file/d/1_v2uCZRaO5-HTqg18cwMIKV4GbM3KSCq/view?usp=drivesdk
A30: 118196 | B30: Лхагважаргал | C30: E(10-Р АНГИ) II-I | D30: 7 | E30: 2 | F30: 0 | G30: 0 | H30: 0 | I30: https://drive.google.com/file/d/1cYlkR-gIRRO_fpKcmqVTu4jFQ0p7NDsw/view?usp=drivesdk | J30: https://drive.google.com/file/d/1Jyi-ATCJNIhFjqgvcfxDAGPO1Us2FBgs/view?usp=drivesdk | K30: https://drive.google.com/file/d/1lr0Jku5Qv5rCNp1ZeiJHf3I8j4ef1OXh/view?usp=drivesdk
A31: 155702 | B31: Фарида | C31: E(10-Р АНГИ) II-I | D31: 1 | E31: 0 | F31: 0 | G31: 0 | H31: 0 | I31: https://drive.google.com/file/d/1F15CvBrYZ9lPGMo469qojv-1G1377lbh/view?usp=drivesdk | J31: https://drive.google.com/file/d/1sP1LdRmFoY1YAMyNZrxzZIEL_edGRtJD/view?usp=drivesdk
A32: 181570 | B32: Амармэнд | C32: E(10-Р АНГИ) II-I | D32: 1 | E32: 2 | F32: 0 | G32: 0 | H32: 0 | I32: https://drive.google.com/file/d/1GzsnhCjpPdKsIACKOa7NzjOzwuSqQYiR/view?usp=drivesdk | J32: https://drive.google.com/file/d/1lu3raFL5xF5uJNYV8Iwa__d54DmHhS31/view?usp=drivesdk | K32: https://drive.google.com/file/d/172xVS9xsd4c7klI-cd8-vg2frysoXRWb/view?usp=drivesdk
A33: 196624 | B33: Тогтохжаргал | C33: E(10-Р АНГИ) II-I | D33: 0 | E33: 0 | F33: 0 | G33: 0 | H33: 0 | I33: https://drive.google.com/file/d/105JwGv7S-DBo9mwbQ7vmHBAeQZr87Yfh/view?usp=drivesdk
A34: 73757 | B34: Тэргэл | C34: E(10-Р АНГИ) II-I | D34: 7 | E34: 3 | F34: 0 | G34: 0 | H34: 0 | I34: https://drive.google.com/file/d/1BhvpjWR2OkhgLN5H5WX8duZudO_wdcI8/view?usp=drivesdk | J34: https://drive.google.com/file/d/1ugMh6HO3h1m9tdcdHUWSAzB-de1fScQX/view?usp=drivesdk | K34: https://drive.google.com/file/d/1q8m0_99C1ITMS43HthBPzPktSx-oJ3zl/view?usp=drivesdk | L34: https://drive.google.com/file/d/195gD17bxdlOHzCf5Dd9_ev3m4DtuO_D6/view?usp=drivesdk | M34: https://drive.google.com/file/d/1TCOtK8CzvZMnE1FDL211ldDIrjFIimLq/view?usp=drivesdk | N34: https://drive.google.com/file/d/1K8-QQM4-YOC2F4egx1QxzxtT4AuY3HaA/view?usp=drivesdk
A35: 183220 | B35: Мөнх-Оргил | C35: E(10-Р АНГИ) II-I | D35: 7 | E35: 2 | F35: 0 | G35: 0 | H35: 0 | I35: https://drive.google.com/file/d/1BeoLs1dKWiWxr06V8SFX_-U1eBzrSRTT/view?usp=drivesdk
A36: 204719 | B36: Ариунзаяа | C36: E(10-Р АНГИ) II-I | D36: 0 | E36: 0 | F36: 0 | G36: 0 | H36: 0 | I36: https://drive.google.com/file/d/1jqZNTnVohdB5KF-wOZOpTq2ZDvc5I0gq/view?usp=drivesdk | J36: https://drive.google.com/file/d/1kCHefsbbdal6fvpIX9wTZAm37IicNKy0/view?usp=drivesdk | K36: https://drive.google.com/file/d/1fLFnFLPS2kA2Asn8ZggpeGT6RQWJtiqO/view?usp=drivesdk
A37: 119856 | B37: Жавхлант | C37: E(10-Р АНГИ) II-I | D37: 0 | E37: 0 | F37: 0 | G37: 0 | H37: 0 | I37: https://drive.google.com/file/d/1sRwW4xq2bwA5Jwek4RUgE8fotwdbQd2n/view?usp=drivesdk
A38: 109300 | B38: Батмөнх | C38: E(10-Р АНГИ) II-I | D38: 7 | E38: 2 | F38: 0 | G38: 0 | H38: 0 | I38: https://drive.google.com/file/d/1VnV9Hy37Kg9y8H78BXm5dLJ_nCZIKsg7/view?usp=drivesdk | J38: https://drive.google.com/file/d/1SkFoaWpdn-XGarY99JoSGHc2Lwd0FNoG/view?usp=drivesdk | K38: https://drive.google.com/file/d/15XTE9GY-85DlPTF4iFSKR7G9GY7kUkFi/view?usp=drivesdk
A39: 174358 | B39: Анужаргал | C39: E(10-Р АНГИ) II-I | D39: 0 | E39: 0 | F39: 0 | G39: 0 | H39: 0 | I39: https://drive.google.com/file/d/17J2sdQ3qzXPnlxOnW73e7FjyEnttOwmi/view?usp=drivesdk
A40: 119874 | B40: Чингүүн | C40: E(10-Р АНГИ) II-I | D40: 7 | E40: 3 | F40: 0 | G40: 0 | H40: 0 | I40: https://drive.google.com/file/d/1ic6rOMdzxjoF1guhgQXVd20wI8BlJsZZ/view?usp=drivesdk | J40: https://drive.google.com/file/d/19ZK_QC1m3Qk4Y2JL1Ij3VkXllFAGzRmc/view?usp=drivesdk
...

Sheet 5-р анги
A1: МОНГОЛЫН МАТЕМАТИКИЙН 62-Р ОЛИМПИАД
A2: 46004 | L2: 5 ДУГААР АНГИ
A3: ID | B3: Ангилал | C3: Сургууль | D3: Нэр | E3: Овог | F3: Анги | G3: Бүлэг | H3: Бод-1 | I3: Бод-2 | J3: Бод-3 | K3: Бод-4 | L3: НИЙТ оноо | M3: Эзэлсэн байр
A4: 196066 | B4: С(5-р анги) II-I | C4: Жаргалант сумын 3-р сургууль | D4: Чингүүн | E4: Төмөрхүү | F4: 5-р анги | G4: в | H4: =VLOOKUP($A4,Day1!$A$1:$H$394,4,FALSE()) -> 7 | I4: =VLOOKUP($A4,Day1!$A$1:$H$394,5,FALSE()) -> 1.5 | J4: =VLOOKUP($A4,Day1!$A$1:$H$394,6,FALSE()) -> 6 | K4: =VLOOKUP($A4,Day1!$A$1:$H$394,7,FALSE()) -> 0 | L4: =SUM(H4:K4) -> 14.5 | M4: =ROMAN(RANK(L4,$L$4:$L$59,0)) -> I
A5: 185254 | B5: С(5-р анги) II-I | C5: Жаргалант сумын Прогресс сургууль | D5: Тэлмэнсайхан | E5: Энхмөнх | F5: 5-р анги | G5: б | H5: =VLOOKUP($A5,Day1!$A$1:$H$394,4,FALSE()) -> 7 | I5: =VLOOKUP($A5,Day1!$A$1:$H$394,5,FALSE()) -> 0 | J5: =VLOOKUP($A5,Day1!$A$1:$H$394,6,FALSE()) -> 7 | K5: =VLOOKUP($A5,Day1!$A$1:$H$394,7,FALSE()) -> 0 | L5: =SUM(H5:K5) -> 14 | M5: =ROMAN(RANK(L5,$L$4:$L$59,0)) -> II
A6: 185192 | B6: С(5-р анги) II-I | C6: Жаргалант сумын Прогресс сургууль | D6: Энхнаран | E6: Хишигжаргал | F6: 5-р анги | G6: в | H6: =VLOOKUP($A6,Day1!$A$1:$H$394,4,FALSE()) -> 0 | I6: =VLOOKUP($A6,Day1!$A$1:$H$394,5,FALSE()) -> 3 | J6: =VLOOKUP($A6,Day1!$A$1:$H$394,6,FALSE()) -> 7 | K6: =VLOOKUP($A6,Day1!$A$1:$H$394,7,FALSE()) -> 0 | L6: =SUM(H6:K6) -> 10 | M6: =ROMAN(RANK(L6,$L$4:$L$59,0)) -> III
A7: 197176 | B7: С(5-р анги) II-I | C7: Жаргалант сумын 7-р сургууль | D7: Мөнгөнбаатар | E7: Баянхүү | F7: 5-р анги | G7: б | H7: =VLOOKUP($A7,Day1!$A$1:$H$394,4,FALSE()) -> 0 | I7: =VLOOKUP($A7,Day1!$A$1:$H$394,5,FALSE()) -> 3 | J7: 6 | K7: =VLOOKUP($A7,Day1!$A$1:$H$394,7,FALSE()) -> 0 | L7: =SUM(H7:K7) -> 9 | M7: =ROMAN(RANK(L7,$L$4:$L$59,0)) -> IV
A8: 185249 | B8: С(5-р анги) II-I | C8: Жаргалант сумын Прогресс сургууль | D8: Идэржавхлан | E8: Даваасүрэн | F8: 5-р анги | G8: б | H8: =VLOOKUP($A8,Day1!$A$1:$H$394,4,FALSE()) -> 7 | I8: =VLOOKUP($A8,Day1!$A$1:$H$394,5,FALSE()) -> 0 | J8: =VLOOKUP($A8,Day1!$A$1:$H$394,6,FALSE()) -> 0 | K8: =VLOOKUP($A8,Day1!$A$1:$H$394,7,FALSE()) -> 1 | L8: =SUM(H8:K8) -> 8 | M8: =ROMAN(RANK(L8,$L$4:$L$59,0)) -> V
A9: 195731 | B9: С(5-р анги) II-I | C9: Жаргалант сумын 3-р сургууль | D9: Тэмүүжин | E9: Ганзориг | F9: 5-р анги | G9: а | H9: =VLOOKUP($A9,Day1!$A$1:$H$394,4,FALSE()) -> 2 | I9: =VLOOKUP($A9,Day1!$A$1:$H$394,5,FALSE()) -> 0 | J9: =VLOOKUP($A9,Day1!$A$1:$H$394,6,FALSE()) -> 5 | K9: =VLOOKUP($A9,Day1!$A$1:$H$394,7,FALSE()) -> 0 | L9: =SUM(H9:K9) -> 7 | M9: =ROMAN(RANK(L9,$L$4:$L$59,0)) -> VI
A10: 185252 | B10: С(5-р анги) II-I | C10: Жаргалант сумын Прогресс сургууль | D10: Номин | E10: Батзориг | F10: 5-р анги | G10: б | H10: =VLOOKUP($A10,Day1!$A$1:$H$394,4,FALSE()) -> 0 | I10: =VLOOKUP($A10,Day1!$A$1:$H$394,5,FALSE()) -> 0 | J10: =VLOOKUP($A10,Day1!$A$1:$H$394,6,FALSE()) -> 6 | K10: =VLOOKUP($A10,Day1!$A$1:$H$394,7,FALSE()) -> 1 | L10: =SUM(H10:K10) -> 7 | M10: =ROMAN(RANK(L10,$L$4:$L$59,0)) -> VI
A11: 196067 | B11: С(5-р анги) II-I | C11: Жаргалант сумын 3-р сургууль | D11: Ган-Очир | E11: Очирбат | F11: 5-р анги | G11: в | H11: =VLOOKUP($A11,Day1!$A$1:$H$394,4,FALSE()) -> 0 | I11: =VLOOKUP($A11,Day1!$A$1:$H$394,5,FALSE()) -> 0 | J11: =VLOOKUP($A11,Day1!$A$1:$H$394,6,FALSE()) -> 5 | K11: =VLOOKUP($A11,Day1!$A$1:$H$394,7,FALSE()) -> 0 | L11: =SUM(H11:K11) -> 5 | M11: =ROMAN(RANK(L11,$L$4:$L$59,0)) -> VIII
A12: 185222 | B12: С(5-р анги) II-I | C12: Жаргалант сумын Прогресс сургууль | D12: Жанерке | E12: Хойчбай | F12: 5-р анги | G12: а | H12: =VLOOKUP($A12,Day1!$A$1:$H$394,4,FALSE()) -> 0 | I12: =VLOOKUP($A12,Day1!$A$1:$H$394,5,FALSE()) -> 0 | J12: =VLOOKUP($A12,Day1!$A$1:$H$394,6,FALSE()) -> 5 | K12: =VLOOKUP($A12,Day1!$A$1:$H$394,7,FALSE()) -> 0 | L12: =SUM(H12:K12) -> 5 | M12: =ROMAN(RANK(L12,$L$4:$L$59,0)) -> VIII
A13: 205622 | B13: С(5-р анги) II-I | C13: Буянт сумын сургууль | D13: Энгүүн | E13: Баасандорж | F13: 5-р анги | G13: б | H13: =VLOOKUP($A13,Day1!$A$1:$H$394,4,FALSE()) -> 5 | I13: =VLOOKUP($A13,Day1!$A$1:$H$394,5,FALSE()) -> 0 | J13: =VLOOKUP($A13,Day1!$A$1:$H$394,6,FALSE()) -> 0 | K13: =VLOOKUP($A13,Day1!$A$1:$H$394,7,FALSE()) -> 0 | L13: =SUM(H13:K13) -> 5 | M13: =ROMAN(RANK(L13,$L$4:$L$59,0)) -> VIII
A14: 185187 | B14: С(5-р анги) II-I | C14: Жаргалант сумын Прогресс сургууль | D14: Дөлгөөнмөрөн | E14: Бүрэнбат | F14: 5-р анги | G14: в | H14: =VLOOKUP($A14,Day1!$A$1:$H$394,4,FALSE()) -> 0 | I14: =VLOOKUP($A14,Day1!$A$1:$H$394,5,FALSE()) -> 3 | J14: =VLOOKUP($A14,Day1!$A$1:$H$394,6,FALSE()) -> 1 | K14: =VLOOKUP($A14,Day1!$A$1:$H$394,7,FALSE()) -> 0 | L14: =SUM(H14:K14) -> 4 | M14: =ROMAN(RANK(L14,$L$4:$L$59,0)) -> XI
A15: 187279 | B15: С(5-р анги) II-I | C15: Эрдэнэбүрэн сумын сургууль | D15: Нямдаваа | E15: Тулга | F15: 5-р анги | G15: а | H15: =VLOOKUP($A15,Day1!$A$1:$H$394,4,FALSE()) -> 2 | I15: =VLOOKUP($A15,Day1!$A$1:$H$394,5,FALSE()) -> 0 | J15: =VLOOKUP($A15,Day1!$A$1:$H$394,6,FALSE()) -> 0 | K15: =VLOOKUP($A15,Day1!$A$1:$H$394,7,FALSE()) -> 0 | L15: =SUM(H15:K15) -> 2 | M15: =ROMAN(RANK(L15,$L$4:$L$59,0)) -> XII
A16: 111961 | B16: С(5-р анги) II-I | C16: Алтай сумын сургууль | D16: Пүрэвсайхан | E16: Энхбаяр | F16: 5-р анги | G16: б | H16: =VLOOKUP($A16,Day1!$A$1:$H$394,4,FALSE()) -> 2 | I16: =VLOOKUP($A16,Day1!$A$1:$H$394,5,FALSE()) -> 0 | J16: =VLOOKUP($A16,Day1!$A$1:$H$394,6,FALSE()) -> 0 | K16: =VLOOKUP($A16,Day1!$A$1:$H$394,7,FALSE()) -> 0 | L16: =SUM(H16:K16) -> 2 | M16: =ROMAN(RANK(L16,$L$4:$L$59,0)) -> XII
A17: 185181 | B17: С(5-р анги) II-I | C17: Жаргалант сумын Прогресс сургууль | D17: Баттөгөлдөр | E17: А | F17: 5-р анги | G17: в | H17: =VLOOKUP($A17,Day1!$A$1:$H$394,4,FALSE()) -> 0 | I17: =VLOOKUP($A17,Day1!$A$1:$H$394,5,FALSE()) -> 2 | J17: =VLOOKUP($A17,Day1!$A$1:$H$394,6,FALSE()) -> 0 | K17: =VLOOKUP($A17,Day1!$A$1:$H$394,7,FALSE()) -> 0 | L17: =SUM(H17:K17) -> 2 | M17: =ROMAN(RANK(L17,$L$4:$L$59,0)) -> XII
A18: 181050 | B18: С(5-р анги) II-I | C18: Жаргалант сумын 1-р сургууль | D18: Билэг-Энэрэл | E18: Төмөрхүү | F18: 5-р анги | G18: а | H18: =VLOOKUP($A18,Day1!$A$1:$H$394,4,FALSE()) -> 2 | I18: =VLOOKUP($A18,Day1!$A$1:$H$394,5,FALSE()) -> 0 | J18: =VLOOKUP($A18,Day1!$A$1:$H$394,6,FALSE()) -> 0 | K18: =VLOOKUP($A18,Day1!$A$1:$H$394,7,FALSE()) -> 0 | L18: =SUM(H18:K18) -> 2 | M18: =ROMAN(RANK(L18,$L$4:$L$59,0)) -> XII
A19: 185241 | B19: С(5-р анги) II-I | C19: Жаргалант сумын Прогресс сургууль | D19: Амгалан | E19: Ганболд | F19: 5-р анги | G19: б | H19: =VLOOKUP($A19,Day1!$A$1:$H$394,4,FALSE()) -> 0 | I19: =VLOOKUP($A19,Day1!$A$1:$H$394,5,FALSE()) -> 0 | J19: =VLOOKUP($A19,Day1!$A$1:$H$394,6,FALSE()) -> 0 | K19: =VLOOKUP($A19,Day1!$A$1:$H$394,7,FALSE()) -> 1 | L19: =SUM(H19:K19) -> 1 | M19: =ROMAN(RANK(L19,$L$4:$L$59,0)) -> XVI
... A59: 111669 | B59: С(5-р анги) II-I | C59: Мөст сумын сургууль | D59: Элбэгсайхан | E59: Ариунболд | F59: 5-р анги | G59: б | H59: =VLOOKUP($A59,Day1!$A$1:$H$394,4,FALSE()) -> 0 | I59: =VLOOKUP($A59,Day1!$A$1:$H$394,5,FALSE()) -> 0 | J59: =VLOOKUP($A59,Day1!$A$1:$H$394,6,FALSE()) -> 0 | K59: =VLOOKUP($A59,Day1!$A$1:$H$394,7,FALSE()) -> 0 | L59: =SUM(H59:K59) -> 0 | M59: =ROMAN(RANK(L59,$L$4:$L$59,0)) -> XXI
A61: Олимпиадыг авсан багш: М.Чагцал, Д.Ганцацрал, Э.Нарантуяа
A63: Олимпиадыгзассан багш: Ц.Бадамханд, З.Батсүлд, Х.Онгорбай, З.Бямбарагчаа

Sheet 6-р анги
A1: МОНГОЛЫН МАТЕМАТИКИЙН 62-Р ОЛИМПИАД
A2: 46004 | J2: 6 ДУГААР АНГИ
A3: ID | B3: Ангилал | C3: Сургууль | D3: Нэр | E3: Овог | F3: Анги | G3: Бүлэг | H3: Бод-1 | I3: Бод-2 | J3: Бод-3 | K3: Бод-4 | L3: НИЙТ оноо | M3: Эзэлсэн байр
A4: 185284 | B4: С(6-р анги) II-I | C4: Жаргалант сумын Прогресс сургууль | D4: Ану | E4: Дорждэрэм | F4: 6-р анги | G4: г | H4: =VLOOKUP($A4,Day1!$A$1:$H$394,4,FALSE()) -> 1.5 | I4: =VLOOKUP($A4,Day1!$A$1:$H$394,5,FALSE()) -> 0 | J4: =VLOOKUP($A4,Day1!$A$1:$H$394,6,FALSE()) -> 6 | K4: =VLOOKUP($A4,Day1!$A$1:$H$394,7,FALSE()) -> 1 | L4: =SUM(H4:K4) -> 8.5 | M4: =ROMAN(RANK(L4,$L$4:$L$74,0)) -> I
A5: 187417 | B5: С(6-р анги) II-I | C5: Жаргалант сумын Цаст-Алтай сургууль | D5: Батцэцэг | E5: Хадбаатар | F5: 6-р анги | G5: д | H5: =VLOOKUP($A5,Day1!$A$1:$H$394,4,FALSE()) -> 1 | I5: =VLOOKUP($A5,Day1!$A$1:$H$394,5,FALSE()) -> 0 | J5: =VLOOKUP($A5,Day1!$A$1:$H$394,6,FALSE()) -> 6 | K5: =VLOOKUP($A5,Day1!$A$1:$H$394,7,FALSE()) -> 1 | L5: =SUM(H5:K5) -> 8 | M5: =ROMAN(RANK(L5,$L$4:$L$74,0)) -> II
A6: 159136 | B6: С(6-р анги) II-I | C6: Жаргалант сумын 1-р сургууль | D6: Галсандаваа | E6: Бүтэхбаяр | F6: 6-р анги | G6: в | H6: =VLOOKUP($A6,Day1!$A$1:$H$394,4,FALSE()) -> 1 | I6: =VLOOKUP($A6,Day1!$A$1:$H$394,5,FALSE()) -> 0 | J6: =VLOOKUP($A6,Day1!$A$1:$H$394,6,FALSE()) -> 7 | K6: =VLOOKUP($A6,Day1!$A$1:$H$394,7,FALSE()) -> 0 | L6: =SUM(H6:K6) -> 8 | M6: =ROMAN(RANK(L6,$L$4:$L$74,0)) -> II | N6: 36000
A7: 185285 | B7: С(6-р анги) II-I | C7: Жаргалант сумын Прогресс сургууль | D7: Есү | E7: Дорждэрэм | F7: 6-р анги | G7: г | H7: =VLOOKUP($A7,Day1!$A$1:$H$394,4,FALSE()) -> 0 | I7: =VLOOKUP($A7,Day1!$A$1:$H$394,5,FALSE()) -> 0 | J7: =VLOOKUP($A7,Day1!$A$1:$H$394,6,FALSE()) -> 6 | K7: =VLOOKUP($A7,Day1!$A$1:$H$394,7,FALSE()) -> 1.5 | L7: =SUM(H7:K7) -> 7.5 | M7: =ROMAN(RANK(L7,$L$4:$L$74,0)) -> IV
A8: 144728 | B8: С(6-р анги) II-I | C8: Жаргалант сумын Цаст-Алтай сургууль | D8: Тогтуунхүслэн | E8: Балдорж | F8: 6-р анги | G8: б | H8: =VLOOKUP($A8,Day1!$A$1:$H$394,4,FALSE()) -> 0 | I8: =VLOOKUP($A8,Day1!$A$1:$H$394,5,FALSE()) -> 2 | J8: =VLOOKUP($A8,Day1!$A$1:$H$394,6,FALSE()) -> 5.5 | K8: =VLOOKUP($A8,Day1!$A$1:$H$394,7,FALSE()) -> 0 | L8: =SUM(H8:K8) -> 7.5 | M8: =ROMAN(RANK(L8,$L$4:$L$74,0)) -> IV | N8: 27000
A9: 162248 | B9: С(6-р анги) II-I | C9: Жаргалант сумын Цаст-Алтай сургууль | D9: Гарьд | E9: Сугарбаяр | F9: 6-р анги | G9: г | H9: =VLOOKUP($A9,Day1!$A$1:$H$394,4,FALSE()) -> 0 | I9: =VLOOKUP($A9,Day1!$A$1:$H$394,5,FALSE()) -> 0 | J9: =VLOOKUP($A9,Day1!$A$1:$H$394,6,FALSE()) -> 6 | K9: =VLOOKUP($A9,Day1!$A$1:$H$394,7,FALSE()) -> 0 | L9: =SUM(H9:K9) -> 6 | M9: =ROMAN(RANK(L9,$L$4:$L$74,0)) -> VI
A10: 131693 | B10: С(6-р анги) II-I | C10: Жаргалант сумын Прогресс сургууль | D10: Эрдэнэбаатар | E10: Баасанжав | F10: 6-р анги | G10: в | H10: =VLOOKUP($A10,Day1!$A$1:$H$394,4,FALSE()) -> 0 | I10: =VLOOKUP($A10,Day1!$A$1:$H$394,5,FALSE()) -> 0 | J10: =VLOOKUP($A10,Day1!$A$1:$H$394,6,FALSE()) -> 6 | K10: =VLOOKUP($A10,Day1!$A$1:$H$394,7,FALSE()) -> 0 | L10: =SUM(H10:K10) -> 6 | M10: =ROMAN(RANK(L10,$L$4:$L$74,0)) -> VI
A11: 131712 | B11: С(6-р анги) II-I | C11: Жаргалант сумын Прогресс сургууль | D11: Мөнхбилэг | E11: Золбаяр | F11: 6-р анги | G11: б | H11: =VLOOKUP($A11,Day1!$A$1:$H$394,4,FALSE()) -> 0 | I11: =VLOOKUP($A11,Day1!$A$1:$H$394,5,FALSE()) -> 0 | J11: =VLOOKUP($A11,Day1!$A$1:$H$394,6,FALSE()) -> 5 | K11: =VLOOKUP($A11,Day1!$A$1:$H$394,7,FALSE()) -> 0 | L11: =SUM(H11:K11) -> 5 | M11: =ROMAN(RANK(L11,$L$4:$L$74,0)) -> VIII
A12: 145506 | B12: С(6-р анги) II-I | C12: Мянгад сумын сургууль | D12: Санчир | E12: Ганбаяр | F12: 6-р анги | G12: б | H12: =VLOOKUP($A12,Day1!$A$1:$H$394,4,FALSE()) -> 0 | I12: =VLOOKUP($A12,Day1!$A$1:$H$394,5,FALSE()) -> 0 | J12: =VLOOKUP($A12,Day1!$A$1:$H$394,6,FALSE()) -> 5 | K12: =VLOOKUP($A12,Day1!$A$1:$H$394,7,FALSE()) -> 0 | L12: =SUM(H12:K12) -> 5 | M12: =ROMAN(RANK(L12,$L$4:$L$74,0)) -> VIII
A13: 124381 | B13: С(6-р анги) II-I | C13: Жаргалант сумын Прогресс сургууль | D13: Очирсүлд | E13: Балдорж | F13: 6-р анги | G13: г | H13: =VLOOKUP($A13,Day1!$A$1:$H$394,4,FALSE()) -> 1 | I13: =VLOOKUP($A13,Day1!$A$1:$H$394,5,FALSE()) -> 0 | J13: =VLOOKUP($A13,Day1!$A$1:$H$394,6,FALSE()) -> 3 | K13: =VLOOKUP($A13,Day1!$A$1:$H$394,7,FALSE()) -> 0 | L13: =SUM(H13:K13) -> 4 | M13: =ROMAN(RANK(L13,$L$4:$L$74,0)) -> X
A14: 124388 | B14: С(6-р анги) II-I | C14: Жаргалант сумын Прогресс сургууль | D14: Баатарсайхан | E14: Баярсайхан | F14: 6-р анги | G14: г | H14: =VLOOKUP($A14,Day1!$A$1:$H$394,4,FALSE()) -> 1 | I14: =VLOOKUP($A14,Day1!$A$1:$H$394,5,FALSE()) -> 0 | J14: =VLOOKUP($A14,Day1!$A$1:$H$394,6,FALSE()) -> 3 | K14: =VLOOKUP($A14,Day1!$A$1:$H$394,7,FALSE()) -> 0 | L14: =SUM(H14:K14) -> 4 | M14: =ROMAN(RANK(L14,$L$4:$L$74,0)) -> X
A15: 124372 | B15: С(6-р анги) II-I | C15: Жаргалант сумын Прогресс сургууль | D15: Анандзаяа | E15: Мөнх-Очир | F15: 6-р анги | G15: г | H15: =VLOOKUP($A15,Day1!$A$1:$H$394,4,FALSE()) -> 1 | I15: =VLOOKUP($A15,Day1!$A$1:$H$394,5,FALSE()) -> 2 | J15: =VLOOKUP($A15,Day1!$A$1:$H$394,6,FALSE()) -> 0 | K15: =VLOOKUP($A15,Day1!$A$1:$H$394,7,FALSE()) -> 0 | L15: =SUM(H15:K15) -> 3 | M15: =ROMAN(RANK(L15,$L$4:$L$74,0)) -> XII
A16: 124387 | B16: С(6-р анги) II-I | C16: Жаргалант сумын Прогресс сургууль | D16: Учрал | E16: Амарбаясгалан | F16: 6-р анги | G16: г | H16: =VLOOKUP($A16,Day1!$A$1:$H$394,4,FALSE()) -> 0 | I16: =VLOOKUP($A16,Day1!$A$1:$H$394,5,FALSE()) -> 0 | J16: =VLOOKUP($A16,Day1!$A$1:$H$394,6,FALSE()) -> 3 | K16: =VLOOKUP($A16,Day1!$A$1:$H$394,7,FALSE()) -> 0 | L16: =SUM(H16:K16) -> 3 | M16: =ROMAN(RANK(L16,$L$4:$L$74,0)) -> XII
A17: 185292 | B17: С(6-р анги) II-I | C17: Жаргалант сумын Прогресс сургууль | D17: Төрмандах | E17: Санжмятав | F17: 6-р анги | G17: г | H17: =VLOOKUP($A17,Day1!$A$1:$H$394,4,FALSE()) -> 0 | I17: =VLOOKUP($A17,Day1!$A$1:$H$394,5,FALSE()) -> 0 | J17: =VLOOKUP($A17,Day1!$A$1:$H$394,6,FALSE()) -> 3 | K17: =VLOOKUP($A17,Day1!$A$1:$H$394,7,FALSE()) -> 0 | L17: =SUM(H17:K17) -> 3 | M17: =ROMAN(RANK(L17,$L$4:$L$74,0)) -> XII
A18: 122516 | B18: С(6-р анги) II-I | C18: Жаргалант сумын 2-р сургууль | D18: Нуртыле | E18: Керекбай | F18: 6-р анги | G18: а | H18: =VLOOKUP($A18,Day1!$A$1:$H$394,4,FALSE()) -> 0 | I18: =VLOOKUP($A18,Day1!$A$1:$H$394,5,FALSE()) -> 0 | J18: =VLOOKUP($A18,Day1!$A$1:$H$394,6,FALSE()) -> 3 | K18: =VLOOKUP($A18,Day1!$A$1:$H$394,7,FALSE()) -> 0 | L18: =SUM(H18:K18) -> 3 | M18: =ROMAN(RANK(L18,$L$4:$L$74,0)) -> XII
A19: 117566 | B19: С(6-р анги) II-I | C19: Дарви сумын сургууль | D19: Сарангуа | E19: Мөнхжаргал | F19: 6-р анги | G19: а | H19: =VLOOKUP($A19,Day1!$A$1:$H$394,4,FALSE()) -> 0 | I19: =VLOOKUP($A19,Day1!$A$1:$H$394,5,FALSE()) -> 0 | J19: =VLOOKUP($A19,Day1!$A$1:$H$394,6,FALSE()) -> 3 | K19: =VLOOKUP($A19,Day1!$A$1:$H$394,7,FALSE()) -> 0 | L19: =SUM(H19:K19) -> 3 | M19: =ROMAN(RANK(L19,$L$4:$L$74,0)) -> XII
A20: 132940 | B20: С(6-р анги) II-I | C20: Жаргалант сумын Прогресс сургууль | D20: Ган-Эрдэнэ | E20: Ганзориг | F20: 6-р анги | G20: в | H20: =VLOOKUP($A20,Day1!$A$1:$H$394,4,FALSE()) -> 2 | I20: =VLOOKUP($A20,Day1!$A$1:$H$394,5,FALSE()) -> 0 | J20: =VLOOKUP($A20,Day1!$A$1:$H$394,6,FALSE()) -> 0 | K20: =VLOOKUP($A20,Day1!$A$1:$H$394,7,FALSE()) -> 0 | L20: =SUM(H20:K20) -> 2 | M20: =ROMAN(RANK(L20,$L$4:$L$74,0)) -> XVII
... A74: 171678 | B74: С(6-р анги) II-I | C74: Дуут сумын сургууль | D74: Наранзаяа | E74: Баянмөнх | F74: 6-р анги | G74: а | H74: =VLOOKUP($A74,Day1!$A$1:$H$394,4,FALSE()) -> 0 | I74: =VLOOKUP($A74,Day1!$A$1:$H$394,5,FALSE()) -> 0 | J74: =VLOOKUP($A74,Day1!$A$1:$H$394,6,FALSE()) -> 0 | K74: =VLOOKUP($A74,Day1!$A$1:$H$394,7,FALSE()) -> 0 | L74: =SUM(H74:K74) -> 0 | M74: =ROMAN(RANK(L74,$L$4:$L$74,0)) -> XLVI
A76: Олимпиадыг авсан багш: М.Чагцал, Д.Ганцацрал, Э.Нарантуяа
A78: Олимпиадыгзассан багш: Ц.Бадамханд, З.Батсүлд, Б.Ганбаяр, Х.Онгорбай

Sheet 7-р анги
A1: МОНГОЛЫН МАТЕМАТИКИЙН 62-Р ОЛИМПИАД
A2: 46005 | J2: 7 ДУГААР АНГИ
A3: ID | B3: Ангилал | C3: Сургууль | D3: Нэр | E3: Овог | F3: Анги | G3: Бүлэг | H3: Бод-1 | I3: Бод-2 | J3: Бод-3 | K3: Бод-4 | L3: НИЙТ оноо | M3: Эзэлсэн байр
A4: 186917 | B4: D(7-р анги) II-I | C4: Жаргалант сумын Прогресс сургууль | D4: Эрхсаран | E4: Энхболд | F4: 7-р анги | G4: в | H4: =VLOOKUP($A4,Day2!$A$1:$H$400,4,FALSE()) -> 4 | I4: =VLOOKUP($A4,Day2!$A$1:$H$400,5,FALSE()) -> 0 | J4: =VLOOKUP($A4,Day2!$A$1:$H$400,6,FALSE()) -> 0 | K4: =VLOOKUP($A4,Day2!$A$1:$H$400,7,FALSE()) -> 0 | L4: =SUM(G4:K4) -> 4 | M4: =ROMAN(RANK(L4,$L$4:$L$51,0)) -> I
A5: 174556 | B5: D(7-р анги) II-I | C5: Жаргалант сумын Цаст-Алтай сургууль | D5: Бадрал | E5: Нармандах | F5: 7-р анги | G5: б | H5: =VLOOKUP($A5,Day2!$A$1:$H$400,4,FALSE()) -> 3 | I5: =VLOOKUP($A5,Day2!$A$1:$H$400,5,FALSE()) -> 0 | J5: =VLOOKUP($A5,Day2!$A$1:$H$400,6,FALSE()) -> 0 | K5: =VLOOKUP($A5,Day2!$A$1:$H$400,7,FALSE()) -> 0 | L5: =SUM(G5:K5) -> 3 | M5: =ROMAN(RANK(L5,$L$4:$L$51,0)) -> II
A6: 192744 | B6: D(7-р анги) II-I | C6: Булган сумын 1-р сургууль | D6: Ананд | E6: Ууганбаяр | F6: 7-р анги | G6: а | H6: =VLOOKUP($A6,Day2!$A$1:$H$400,4,FALSE()) -> 2 | I6: =VLOOKUP($A6,Day2!$A$1:$H$400,5,FALSE()) -> 0 | J6: =VLOOKUP($A6,Day2!$A$1:$H$400,6,FALSE()) -> 0 | K6: =VLOOKUP($A6,Day2!$A$1:$H$400,7,FALSE()) -> 0 | L6: =SUM(G6:K6) -> 2 | M6: =ROMAN(RANK(L6,$L$4:$L$51,0)) -> III
A7: 188003 | B7: D(7-р анги) II-I | C7: Алтай сумын сургууль | D7: Энхжаргал | E7: Цагаандалай | F7: 7-р анги | G7: б | H7: =VLOOKUP($A7,Day2!$A$1:$H$400,4,FALSE()) -> 0 | I7: =VLOOKUP($A7,Day2!$A$1:$H$400,5,FALSE()) -> 0 | J7: =VLOOKUP($A7,Day2!$A$1:$H$400,6,FALSE()) -> 0 | K7: =VLOOKUP($A7,Day2!$A$1:$H$400,7,FALSE()) -> 0 | L7: =SUM(G7:K7) -> 0 | M7: =ROMAN(RANK(L7,$L$4:$L$51,0)) -> IV
A8: 175004 | B8: D(7-р анги) II-I | C8: Жаргалант сумын 2-р сургууль | D8: Чингүүн | E8: Буяннэмэх | F8: 7-р анги | G8: а | H8: =VLOOKUP($A8,Day2!$A$1:$H$400,4,FALSE()) -> 0 | I8: =VLOOKUP($A8,Day2!$A$1:$H$400,5,FALSE()) -> 0 | J8: =VLOOKUP($A8,Day2!$A$1:$H$400,6,FALSE()) -> 0 | K8: =VLOOKUP($A8,Day2!$A$1:$H$400,7,FALSE()) -> 0 | L8: =SUM(G8:K8) -> 0 | M8: =ROMAN(RANK(L8,$L$4:$L$51,0)) -> IV
A9: 196042 | B9: D(7-р анги) II-I | C9: Жаргалант сумын 3-р сургууль | D9: Энх-Амгалан | E9: Төмөрхүү | F9: 7-р анги | G9: а | H9: =VLOOKUP($A9,Day2!$A$1:$H$400,4,FALSE()) -> 0 | I9: =VLOOKUP($A9,Day2!$A$1:$H$400,5,FALSE()) -> 0 | J9: =VLOOKUP($A9,Day2!$A$1:$H$400,6,FALSE()) -> 0 | K9: =VLOOKUP($A9,Day2!$A$1:$H$400,7,FALSE()) -> 0 | L9: =SUM(G9:K9) -> 0 | M9: =ROMAN(RANK(L9,$L$4:$L$51,0)) -> IV
A10: 88991 | B10: D(7-р анги) II-I | C10: Жаргалант сумын 6-р сургууль | D10: Энхтүвшин | E10: Гантулга | F10: 7-р анги | G10: б | H10: =VLOOKUP($A10,Day2!$A$1:$H$400,4,FALSE()) -> 0 | I10: =VLOOKUP($A10,Day2!$A$1:$H$400,5,FALSE()) -> 0 | J10: =VLOOKUP($A10,Day2!$A$1:$H$400,6,FALSE()) -> 0 | K10: =VLOOKUP($A10,Day2!$A$1:$H$400,7,FALSE()) -> 0 | L10: =SUM(G10:K10) -> 0 | M10: =ROMAN(RANK(L10,$L$4:$L$51,0)) -> IV
A11: 88997 | B11: D(7-р анги) II-I | C11: Жаргалант сумын 6-р сургууль | D11: Мянганбаяр | E11: Одонхүү | F11: 7-р анги | G11: а | H11: =VLOOKUP($A11,Day2!$A$1:$H$400,4,FALSE()) -> 0 | I11: =VLOOKUP($A11,Day2!$A$1:$H$400,5,FALSE()) -> 0 | J11: =VLOOKUP($A11,Day2!$A$1:$H$400,6,FALSE()) -> 0 | K11: =VLOOKUP($A11,Day2!$A$1:$H$400,7,FALSE()) -> 0 | L11: =SUM(G11:K11) -> 0 | M11: =ROMAN(RANK(L11,$L$4:$L$51,0)) -> IV
A12: 124028 | B12: D(7-р анги) II-I | C12: Жаргалант сумын 6-р сургууль | D12: Цэлмэг | E12: Отгонбаяр | F12: 7-р анги | G12: а | H12: =VLOOKUP($A12,Day2!$A$1:$H$400,4,FALSE()) -> 0 | I12: =VLOOKUP($A12,Day2!$A$1:$H$400,5,FALSE()) -> 0 | J12: =VLOOKUP($A12,Day2!$A$1:$H$400,6,FALSE()) -> 0 | K12: =VLOOKUP($A12,Day2!$A$1:$H$400,7,FALSE()) -> 0 | L12: =SUM(G12:K12) -> 0 | M12: =ROMAN(RANK(L12,$L$4:$L$51,0)) -> IV
A13: 196638 | B13: D(7-р анги) II-I | C13: Жаргалант сумын 7-р сургууль | D13: Энхзаяа | E13: Алтансүх | F13: 7-р анги | G13: а | H13: =VLOOKUP($A13,Day2!$A$1:$H$400,4,FALSE()) -> 0 | I13: =VLOOKUP($A13,Day2!$A$1:$H$400,5,FALSE()) -> 0 | J13: =VLOOKUP($A13,Day2!$A$1:$H$400,6,FALSE()) -> 0 | K13: =VLOOKUP($A13,Day2!$A$1:$H$400,7,FALSE()) -> 0 | L13: =SUM(G13:K13) -> 0 | M13: =ROMAN(RANK(L13,$L$4:$L$51,0)) -> IV
A14: 83909 | B14: D(7-р анги) II-I | C14: Жаргалант сумын Прогресс сургууль | D14: Бүрэнтөгс | E14: Сайнбаяр | F14: 7-р анги | G14: г | H14: =VLOOKUP($A14,Day2!$A$1:$H$400,4,FALSE()) -> 0 | I14: =VLOOKUP($A14,Day2!$A$1:$H$400,5,FALSE()) -> 0 | J14: =VLOOKUP($A14,Day2!$A$1:$H$400,6,FALSE()) -> 0 | K14: =VLOOKUP($A14,Day2!$A$1:$H$400,7,FALSE()) -> 0 | L14: =SUM(G14:K14) -> 0 | M14: =ROMAN(RANK(L14,$L$4:$L$51,0)) -> IV
A15: 83920 | B15: D(7-р анги) II-I | C15: Жаргалант сумын Прогресс сургууль | D15: Хулан | E15: Балчиг | F15: 7-р анги | G15: г | H15: =VLOOKUP($A15,Day2!$A$1:$H$400,4,FALSE()) -> 0 | I15: =VLOOKUP($A15,Day2!$A$1:$H$400,5,FALSE()) -> 0 | J15: =VLOOKUP($A15,Day2!$A$1:$H$400,6,FALSE()) -> 0 | K15: =VLOOKUP($A15,Day2!$A$1:$H$400,7,FALSE()) -> 0 | L15: =SUM(G15:K15) -> 0 | M15: =ROMAN(RANK(L15,$L$4:$L$51,0)) -> IV
... A51: 213249 | B51: D(7-р анги) II-I | C51: Чандмань сумын сургууль | D51: Оюунбилэг | E51: Сүхбаатар | F51: 7-р анги | G51: а | H51: =VLOOKUP($A51,Day2!$A$1:$H$400,4,FALSE()) -> 0 | I51: =VLOOKUP($A51,Day2!$A$1:$H$400,5,FALSE()) -> 0 | J51: =VLOOKUP($A51,Day2!$A$1:$H$400,6,FALSE()) -> 0 | K51: =VLOOKUP($A51,Day2!$A$1:$H$400,7,FALSE()) -> 0 | L51: =SUM(G51:K51) -> 0 | M51: =ROMAN(RANK(L51,$L$4:$L$51,0)) -> IV
A53: Олимпиадыг авсан багш: А.Уламбаяр, Б.Хоролсүрэн, С.Чанцалмаа
A55: Олимпиадыгзассан багш: Ц.Бадамханд, З.Батсүлд, Б.Ганбаяр, Х.Онгорбай

Sheet 8-р анги
A1: МОНГОЛЫН МАТЕМАТИКИЙН 62-Р ОЛИМПИАД
A2: 46005 | J2: 9 ДҮГЭЭР АНГИ
A3: ID | B3: Ангилал | C3: Сургууль | D3: Нэр | E3: Овог | F3: Анги | G3: Бүлэг | H3: Бод-1 | I3: Бод-2 | J3: Бод-3 | K3: Бод-4 | L3: НИЙТ оноо | M3: Эзэлсэн байр
A4: 155596 | B4: D(8-р анги) II-I | C4: Жаргалант сумын 1-р сургууль | D4: Амин-Эрдэнэ | E4: Алтанхуяг | F4: 8-р анги | G4: г | H4: =VLOOKUP($A4,Day2!$A$1:$H$400,4,FALSE()) -> 4 | I4: =VLOOKUP($A4,Day2!$A$1:$H$400,5,FALSE()) -> 7 | J4: =VLOOKUP($A4,Day2!$A$1:$H$400,6,FALSE()) -> 0 | K4: =VLOOKUP($A4,Day2!$A$1:$H$400,7,FALSE()) -> 0 | L4: =SUM(G4:K4) -> 11 | M4: =ROMAN(RANK(L4,$L$4:$L$54,0)) -> I
A5: 207261 | B5: D(8-р анги) II-I | C5: Буянт сумын сургууль | D5: Энхзаяа | E5: Төвсайхан | F5: 8-р анги | G5: а | H5: =VLOOKUP($A5,Day2!$A$1:$H$400,4,FALSE()) -> 0 | I5: =VLOOKUP($A5,Day2!$A$1:$H$400,5,FALSE()) -> 0 | J5: =VLOOKUP($A5,Day2!$A$1:$H$400,6,FALSE()) -> 0 | K5: =VLOOKUP($A5,Day2!$A$1:$H$400,7,FALSE()) -> 7 | L5: =SUM(G5:K5) -> 7 | M5: =ROMAN(RANK(L5,$L$4:$L$54,0)) -> II
A6: 110302 | B6: D(8-р анги) II-I | C6: Жаргалант сумын 1-р сургууль | D6: Хонгорзул | E6: Идэр | F6: 8-р анги | G6: а | H6: =VLOOKUP($A6,Day2!$A$1:$H$400,4,FALSE()) -> 0 | I6: =VLOOKUP($A6,Day2!$A$1:$H$400,5,FALSE()) -> 6 | J6: =VLOOKUP($A6,Day2!$A$1:$H$400,6,FALSE()) -> 0 | K6: =VLOOKUP($A6,Day2!$A$1:$H$400,7,FALSE()) -> 0 | L6: =SUM(G6:K6) -> 6 | M6: =ROMAN(RANK(L6,$L$4:$L$54,0)) -> III
A7: 72374 | B7: D(8-р анги) II-I | C7: Жаргалант сумын Цаст-Алтай сургууль | D7: Аззаяа | E7: Баасанжав | F7: 8-р анги | G7: в | H7: =VLOOKUP($A7,Day2!$A$1:$H$400,4,FALSE()) -> 0 | I7: =VLOOKUP($A7,Day2!$A$1:$H$400,5,FALSE()) -> 0 | J7: =VLOOKUP($A7,Day2!$A$1:$H$400,6,FALSE()) -> 5 | K7: =VLOOKUP($A7,Day2!$A$1:$H$400,7,FALSE()) -> 0 | L7: =SUM(G7:K7) -> 5 | M7: =ROMAN(RANK(L7,$L$4:$L$54,0)) -> IV
A8: 72378 | B8: D(8-р анги) II-I | C8: Жаргалант сумын Цаст-Алтай сургууль | D8: Анхилуун | E8: Доржпүрэв | F8: 8-р анги | G8: г | H8: =VLOOKUP($A8,Day2!$A$1:$H$400,4,FALSE()) -> 0 | I8: =VLOOKUP($A8,Day2!$A$1:$H$400,5,FALSE()) -> 0 | J8: =VLOOKUP($A8,Day2!$A$1:$H$400,6,FALSE()) -> 5 | K8: =VLOOKUP($A8,Day2!$A$1:$H$400,7,FALSE()) -> 0 | L8: =SUM(G8:K8) -> 5 | M8: =ROMAN(RANK(L8,$L$4:$L$54,0)) -> IV
A9: 83902 | B9: D(8-р анги) II-I | C9: Жаргалант сумын Прогресс сургууль | D9: Соёлтогтох | E9: Баттулга | F9: 8-р анги | G9: г | H9: =VLOOKUP($A9,Day2!$A$1:$H$400,4,FALSE()) -> 1 | I9: =VLOOKUP($A9,Day2!$A$1:$H$400,5,FALSE()) -> 0 | J9: =VLOOKUP($A9,Day2!$A$1:$H$400,6,FALSE()) -> 2 | K9: =VLOOKUP($A9,Day2!$A$1:$H$400,7,FALSE()) -> 0 | L9: =SUM(G9:K9) -> 3 | M9: =ROMAN(RANK(L9,$L$4:$L$54,0)) -> VI
A10: 110920 | B10: D(8-р анги) II-I | C10: Алтай сумын сургууль | D10: Энгүүн | E10: Дэлгэр | F10: 8-р анги | G10: б | H10: =VLOOKUP($A10,Day2!$A$1:$H$400,4,FALSE()) -> 2 | I10: =VLOOKUP($A10,Day2!$A$1:$H$400,5,FALSE()) -> 0 | J10: =VLOOKUP($A10,Day2!$A$1:$H$400,6,FALSE()) -> 0 | K10: =VLOOKUP($A10,Day2!$A$1:$H$400,7,FALSE()) -> 0 | L10: =SUM(G10:K10) -> 2 | M10: =ROMAN(RANK(L10,$L$4:$L$54,0)) -> VII
A11: 72372 | B11: D(8-р анги) II-I | C11: Жаргалант сумын Цаст-Алтай сургууль | D11: Ариунцэцэг | E11: Ганцоож | F11: 8-р анги | G11: г | H11: =VLOOKUP($A11,Day2!$A$1:$H$400,4,FALSE()) -> 2 | I11: =VLOOKUP($A11,Day2!$A$1:$H$400,5,FALSE()) -> 0 | J11: =VLOOKUP($A11,Day2!$A$1:$H$400,6,FALSE()) -> 0 | K11: =VLOOKUP($A11,Day2!$A$1:$H$400,7,FALSE()) -> 0 | L11: =SUM(G11:K11) -> 2 | M11: =ROMAN(RANK(L11,$L$4:$L$54,0)) -> VII
A12: 136384 | B12: D(8-р анги) II-I | C12: Жаргалант сумын Цаст-Алтай сургууль | D12: Мягмарсүрэн | E12: Отгоншар | F12: 8-р анги | G12: г | H12: =VLOOKUP($A12,Day2!$A$1:$H$400,4,FALSE()) -> 2 | I12: =VLOOKUP($A12,Day2!$A$1:$H$400,5,FALSE()) -> 0 | J12: =VLOOKUP($A12,Day2!$A$1:$H$400,6,FALSE()) -> 0 | K12: =VLOOKUP($A12,Day2!$A$1:$H$400,7,FALSE()) -> 0 | L12: =SUM(G12:K12) -> 2 | M12: =ROMAN(RANK(L12,$L$4:$L$54,0)) -> VII
A13: 6061 | B13: D(8-р анги) II-I | C13: Жаргалант сумын Прогресс сургууль | D13: Цэцэгбал | E13: Цэнд-Аюуш | F13: 8-р анги | G13: г | H13: =VLOOKUP($A13,Day2!$A$1:$H$400,4,FALSE()) -> 2 | I13: =VLOOKUP($A13,Day2!$A$1:$H$400,5,FALSE()) -> 0 | J13: =VLOOKUP($A13,Day2!$A$1:$H$400,6,FALSE()) -> 0 | K13: =VLOOKUP($A13,Day2!$A$1:$H$400,7,FALSE()) -> 0 | L13: =SUM(G13:K13) -> 2 | M13: =ROMAN(RANK(L13,$L$4:$L$54,0)) -> VII
A14: 111048 | B14: D(8-р анги) II-I | C14: Буянт сумын сургууль | D14: Ялгуунсар | E14: Баасандорж | F14: 8-р анги | G14: б | H14: =VLOOKUP($A14,Day2!$A$1:$H$400,4,FALSE()) -> 1 | I14: =VLOOKUP($A14,Day2!$A$1:$H$400,5,FALSE()) -> 0 | J14: =VLOOKUP($A14,Day2!$A$1:$H$400,6,FALSE()) -> 0 | K14: =VLOOKUP($A14,Day2!$A$1:$H$400,7,FALSE()) -> 0 | L14: =SUM(G14:K14) -> 1 | M14: =ROMAN(RANK(L14,$L$4:$L$54,0)) -> XI
A15: 118416 | B15: D(8-р анги) II-I | C15: Жаргалант сумын Прогресс сургууль | D15: Энхжин | E15: Гантулга | F15: 8-р анги | G15: г | H15: =VLOOKUP($A15,Day2!$A$1:$H$400,4,FALSE()) -> 0 | I15: =VLOOKUP($A15,Day2!$A$1:$H$400,5,FALSE()) -> 0 | J15: =VLOOKUP($A15,Day2!$A$1:$H$400,6,FALSE()) -> 0 | K15: =VLOOKUP($A15,Day2!$A$1:$H$400,7,FALSE()) -> 1 | L15: =SUM(G15:K15) -> 1 | M15: =ROMAN(RANK(L15,$L$4:$L$54,0)) -> XI
... A35: 185342 | B35: D(8-р анги) II-I | C35: Жаргалант сумын Прогресс сургууль | D35: Үжин | E35: Б | F35: 8-р анги | G35: г | H35: =VLOOKUP($A35,Day2!$A$1:$H$400,4,FALSE()) -> 0 | I35: =VLOOKUP($A35,Day2!$A$1:$H$400,5,FALSE()) -> 0 | J35: =VLOOKUP($A35,Day2!$A$1:$H$400,6,FALSE()) -> 0 | K35: =VLOOKUP($A35,Day2!$A$1:$H$400,7,FALSE()) -> 0 | L35: =SUM(G35:K35) -> 0 | M35: =ROMAN(RANK(L35,$L$4:$L$54,0)) -> XIII
A36: 185346 | B36: D(8-р анги) II-I | C36: Жаргалант сумын Прогресс сургууль | D36: Энхсувд | E36: Амарсайхан | F36: 8-р анги | G36: г | L36: =SUM(G36:K36) -> 0 | M36: =ROMAN(RANK(L36,$L$4:$L$54,0)) -> XIII
A37: 72328 | B37: D(8-р анги) II-I | C37: Жаргалант сумын Цаст-Алтай сургууль | D37: Наранбаяр | E37: Эрдэнэ-Очир | F37: 8-р анги | G37: г | H37: =VLOOKUP($A37,Day2!$A$1:$H$400,4,FALSE()) -> 0 | I37: =VLOOKUP($A37,Day2!$A$1:$H$400,5,FALSE()) -> 0 | J37: =VLOOKUP($A37,Day2!$A$1:$H$400,6,FALSE()) -> 0 | K37: =VLOOKUP($A37,Day2!$A$1:$H$400,7,FALSE()) -> 0 | L37: =SUM(G37:K37) -> 0 | M37: =ROMAN(RANK(L37,$L$4:$L$54,0)) -> XIII
A38: 88983 | B38: D(8-р анги) II-I | C38: Жаргалант сумын 6-р сургууль | D38: Энхрий | E38: Ганболор | F38: 8-р анги | G38: в | H38: =VLOOKUP($A38,Day2!$A$1:$H$400,4,FALSE()) -> 0 | I38: =VLOOKUP($A38,Day2!$A$1:$H$400,5,FALSE()) -> 0 | J38: =VLOOKUP($A38,Day2!$A$1:$H$400,6,FALSE()) -> 0 | K38: =VLOOKUP($A38,Day2!$A$1:$H$400,7,FALSE()) -> 0 | L38: =SUM(G38:K38) -> 0 | M38: =ROMAN(RANK(L38,$L$4:$L$54,0)) -> XIII
A39: 72495 | B39: D(8-р анги) II-I | C39: Жаргалант сумын Цаст-Алтай сургууль | D39: Ангараг | E39: Мөнгөншагай | F39: 8-р анги | G39: б | H39: =VLOOKUP($A39,Day2!$A$1:$H$400,4,FALSE()) -> 0 | I39: =VLOOKUP($A39,Day2!$A$1:$H$400,5,FALSE()) -> 0 | J39: =VLOOKUP($A39,Day2!$A$1:$H$400,6,FALSE()) -> 0 | K39: =VLOOKUP($A39,Day2!$A$1:$H$400,7,FALSE()) -> 0 | L39: =SUM(G39:K39) -> 0 | M39: =ROMAN(RANK(L39,$L$4:$L$54,0)) -> XIII
A40: 74034 | B40: D(8-р анги) II-I | C40: Жаргалант сумын Цаст-Алтай сургууль | D40: Мөнхбадрал | E40: Ачлалт | F40: 8-р анги | G40: а | L40: =SUM(G40:K40) -> 0 | M40: =ROMAN(RANK(L40,$L$4:$L$54,0)) -> XIII
A41: 74035 | B41: D(8-р анги) II-I | C41: Жаргалант сумын Цаст-Алтай сургууль | D41: Оргил | E41: Батчулуун | F41: 8-р анги | G41: а | L41: =SUM(G41:K41) -> 0 | M41: =ROMAN(RANK(L41,$L$4:$L$54,0)) -> XIII
A42: 187776 | B42: D(8-р анги) II-I | C42: Жаргалант сумын Цаст-Алтай сургууль | D42: Алтжин | E42: Нямдаваа | F42: 8-р анги | G42: а | H42: =VLOOKUP($A42,Day2!$A$1:$H$400,4,FALSE()) -> 0 | I42: =VLOOKUP($A42,Day2!$A$1:$H$400,5,FALSE()) -> 0 | J42: =VLOOKUP($A42,Day2!$A$1:$H$400,6,FALSE()) -> 0 | K42: =VLOOKUP($A42,Day2!$A$1:$H$400,7,FALSE()) -> 0 | L42: =SUM(G42:K42) -> 0 | M42: =ROMAN(RANK(L42,$L$4:$L$54,0)) -> XIII
A43: 187800 | B43: D(8-р анги) II-I | C43: Жаргалант сумын Цаст-Алтай сургууль | D43: Ариунзаяа | E43: Баттулга | F43: 8-р анги | G43: а | H43: =VLOOKUP($A43,Day2!$A$1:$H$400,4,FALSE()) -> 0 | I43: =VLOOKUP($A43,Day2!$A$1:$H$400,5,FALSE()) -> 0 | J43: =VLOOKUP($A43,Day2!$A$1:$H$400,6,FALSE()) -> 0 | K43: =VLOOKUP($A43,Day2!$A$1:$H$400,7,FALSE()) -> 0 | L43: =SUM(G43:K43) -> 0 | M43: =ROMAN(RANK(L43,$L$4:$L$54,0)) -> XIII
A44: 88984 | B44: D(8-р анги) II-I | C44: Жаргалант сумын 6-р сургууль | D44: Ганзаяа | E44: Бат-Эрдэнэ | F44: 8-р анги | G44: в | H44: =VLOOKUP($A44,Day2!$A$1:$H$400,4,FALSE()) -> 0 | I44: =VLOOKUP($A44,Day2!$A$1:$H$400,5,FALSE()) -> 0 | J44: =VLOOKUP($A44,Day2!$A$1:$H$400,6,FALSE()) -> 0 | K44: =VLOOKUP($A44,Day2!$A$1:$H$400,7,FALSE()) -> 0 | L44: =SUM(G44:K44) -> 0 | M44: =ROMAN(RANK(L44,$L$4:$L$54,0)) -> XIII
A45: 124324 | B45: D(8-р анги) II-I | C45: Жаргалант сумын 6-р сургууль | D45: Аньс | E45: Алтанхуяг | F45: 8-р анги | G45: в | H45: =VLOOKUP($A45,Day2!$A$1:$H$400,4,FALSE()) -> 0 | I45: =VLOOKUP($A45,Day2!$A$1:$H$400,5,FALSE()) -> 0 | J45: =VLOOKUP($A45,Day2!$A$1:$H$400,6,FALSE()) -> 0 | K45: =VLOOKUP($A45,Day2!$A$1:$H$400,7,FALSE()) -> 0 | L45: =SUM(G45:K45) -> 0 | M45: =ROMAN(RANK(L45,$L$4:$L$54,0)) -> XIII
A46: 161745 | B46: D(8-р анги) II-I | C46: Жаргалант сумын 6-р сургууль | D46: Болормаа | E46: Цагаач | F46: 8-р анги | G46: б | H46: =VLOOKUP($A46,Day2!$A$1:$H$400,4,FALSE()) -> 0 | I46: =VLOOKUP($A46,Day2!$A$1:$H$400,5,FALSE()) -> 0 | J46: =VLOOKUP($A46,Day2!$A$1:$H$400,6,FALSE()) -> 0 | K46: =VLOOKUP($A46,Day2!$A$1:$H$400,7,FALSE()) -> 0 | L46: =SUM(G46:K46) -> 0 | M46: =ROMAN(RANK(L46,$L$4:$L$54,0)) -> XIII
A47: 111183 | B47: D(8-р анги) II-I | C47: Жаргалант сумын 7-р сургууль | D47: Азжаргал | E47: Мөнхөө | F47: 8-р анги | G47: д | H47: =VLOOKUP($A47,Day2!$A$1:$H$400,4,FALSE()) -> 0 | I47: =VLOOKUP($A47,Day2!$A$1:$H$400,5,FALSE()) -> 0 | J47: =VLOOKUP($A47,Day2!$A$1:$H$400,6,FALSE()) -> 0 | K47: =VLOOKUP($A47,Day2!$A$1:$H$400,7,FALSE()) -> 0 | L47: =SUM(G47:K47) -> 0 | M47: =ROMAN(RANK(L47,$L$4:$L$54,0)) -> XIII
A48: 83897 | B48: D(8-р анги) II-I | C48: Жаргалант сумын Прогресс сургууль | D48: Марал | E48: Батмонгол | F48: 8-р анги | G48: г | H48: =VLOOKUP($A48,Day2!$A$1:$H$400,4,FALSE()) -> 0 | I48: =VLOOKUP($A48,Day2!$A$1:$H$400,5,FALSE()) -> 0 | J48: =VLOOKUP($A48,Day2!$A$1:$H$400,6,FALSE()) -> 0 | K48: =VLOOKUP($A48,Day2!$A$1:$H$400,7,FALSE()) -> 0 | L48: =SUM(G48:K48) -> 0 | M48: =ROMAN(RANK(L48,$L$4:$L$54,0)) -> XIII
A49: 83901 | B49: D(8-р анги) II-I | C49: Жаргалант сумын Прогресс сургууль | D49: Отгонболор | E49: Баттөмөр | F49: 8-р анги | G49: г | H49: =VLOOKUP($A49,Day2!$A$1:$H$400,4,FALSE()) -> 0 | I49: =VLOOKUP($A49,Day2!$A$1:$H$400,5,FALSE()) -> 0 | J49: =VLOOKUP($A49,Day2!$A$1:$H$400,6,FALSE()) -> 0 | K49: =VLOOKUP($A49,Day2!$A$1:$H$400,7,FALSE()) -> 0 | L49: =SUM(G49:K49) -> 0 | M49: =ROMAN(RANK(L49,$L$4:$L$54,0)) -> XIII
A50: 187822 | B50: D(8-р анги) II-I | C50: Жаргалант сумын Цаст-Алтай сургууль | D50: Намуунзаяа | E50: Амартүвшин | F50: 8-р анги | G50: а | H50: =VLOOKUP($A50,Day2!$A$1:$H$400,4,FALSE()) -> 0 | I50: =VLOOKUP($A50,Day2!$A$1:$H$400,5,FALSE()) -> 0 | J50: =VLOOKUP($A50,Day2!$A$1:$H$400,6,FALSE()) -> 0 | K50: =VLOOKUP($A50,Day2!$A$1:$H$400,7,FALSE()) -> 0 | L50: =SUM(G50:K50) -> 0 | M50: =ROMAN(RANK(L50,$L$4:$L$54,0)) -> XIII
A51: 109008 | B51: D(8-р анги) II-I | C51: Үенч сумын сургууль | D51: Одмаа | E51: Отгонбаяр | F51: 8-р анги | G51: а | H51: =VLOOKUP($A51,Day2!$A$1:$H$400,4,FALSE()) -> 0 | I51: =VLOOKUP($A51,Day2!$A$1:$H$400,5,FALSE()) -> 0 | J51: =VLOOKUP($A51,Day2!$A$1:$H$400,6,FALSE()) -> 0 | K51: =VLOOKUP($A51,Day2!$A$1:$H$400,7,FALSE()) -> 0 | L51: =SUM(G51:K51) -> 0 | M51: =ROMAN(RANK(L51,$L$4:$L$54,0)) -> XIII
A52: 126050 | B52: D(8-р анги) II-I | C52: Цэцэг сумын сургууль | D52: Батбаян | E52: Сүхбаатар | F52: 8-р анги | G52: б | H52: =VLOOKUP($A52,Day2!$A$1:$H$400,4,FALSE()) -> 0 | I52: =VLOOKUP($A52,Day2!$A$1:$H$400,5,FALSE()) -> 0 | J52: =VLOOKUP($A52,Day2!$A$1:$H$400,6,FALSE()) -> 0 | K52: =VLOOKUP($A52,Day2!$A$1:$H$400,7,FALSE()) -> 0 | L52: =SUM(G52:K52) -> 0 | M52: =ROMAN(RANK(L52,$L$4:$L$54,0)) -> XIII
A53: 126053 | B53: D(8-р анги) II-I | C53: Цэцэг сумын сургууль | D53: Ганням | E53: Ганбат | F53: 8-р анги | G53: б | H53: =VLOOKUP($A53,Day2!$A$1:$H$400,4,FALSE()) -> 0 | I53: =VLOOKUP($A53,Day2!$A$1:$H$400,5,FALSE()) -> 0 | J53: =VLOOKUP($A53,Day2!$A$1:$H$400,6,FALSE()) -> 0 | K53: =VLOOKUP($A53,Day2!$A$1:$H$400,7,FALSE()) -> 0 | L53: =SUM(G53:K53) -> 0 | M53: =ROMAN(RANK(L53,$L$4:$L$54,0)) -> XIII
